Workbook

Sheet Cover
B3: FASL (فصل) — Comprehensive Financial Model
B7: The Clinical Intelligence Platform for Saudi Arabia & GCC
B9: FASL Financial Model v1.0 — March 2026
B12: TABLE OF CONTENTS
B13: Tab 1 | C13: Assumptions & Drivers | E13: All model inputs in one place
B14: Tab 2 | C14: Revenue Model | E14: Bottom-up 6-stream revenue build
B15: Tab 3 | C15: P&L Statement | E15: Full income statement Years 1-10
B16: Tab 4 | C16: Unit Economics | E16: ACV, CAC, LTV by segment
B17: Tab 5 | C17: Cash Flow | E17: Operating, investing, financing flows
B18: Tab 6 | C18: Cap Table | E18: 3 rounds + ESOP dilution
B19: Tab 7 | C19: Valuation | E19: 4 exit scenarios with IRR/MOIC
B20: Tab 8 | C20: Sensitivity | E20: Bear / Base / Bull scenarios
B21: Tab 9 | C21: Intercompany | E21: Internal transfer pricing & flows
B22: Tab 10 | C22: KPI Dashboard | E22: Visual charts & metrics
B23: Tab 11 | C23: Use of Proceeds | E23: Capital deployment by round
B26: Currency: USD (toggle SAR × 3.75)
B27: Units: $M (millions) unless noted
B28: Projection Period: 10 years (Year 0 – Year 10)

Sheet 1. Assumptions
A1: FASL FINANCIAL MODEL — KEY ASSUMPTIONS
A2: Assumption | B2: Year 0 | C2: Year 1 | D2: Year 2 | E2: Year 3 | F2: Year 4 | G2: Year 5 | H2: Year 6 | I2: Year 7 | J2: Year 8 | K2: Year 9 | L2: Year 10
A3: Currency
A4: USD/SAR Exchange Rate | B4: 3.75 | C4: 3.75 | D4: 3.75 | E4: 3.75 | F4: 3.75 | G4: 3.75 | H4: 3.75 | I4: 3.75 | J4: 3.75 | K4: 3.75 | L4: 3.75
A5: Market Assumptions
A6: TAM — Saudi Healthcare Spend ($B) | B6: 80 | C6: 80 | D6: 80 | E6: 80 | F6: 80 | G6: 80 | H6: 80 | I6: 80 | J6: 80 | K6: 80 | L6: 80
A7: SAM — Clinical Intelligence ($B) | B7: 2.5 | C7: 2.5 | D7: 2.5 | E7: 2.5 | F7: 2.5 | G7: 2.5 | H7: 2.5 | I7: 2.5 | J7: 2.5 | K7: 2.5 | L7: 2.5
A8: Total Physicians KSA | B8: 90000 | C8: 90000 | D8: 90000 | E8: 90000 | F8: 90000 | G8: 90000 | H8: 90000 | I8: 90000 | J8: 90000 | K8: 90000 | L8: 90000
A9: Total Physicians GCC | B9: 200000 | C9: 200000 | D9: 200000 | E9: 200000 | F9: 200000 | G9: 200000 | H9: 200000 | I9: 200000 | J9: 200000 | K9: 200000 | L9: 200000
A10: Target Hospitals KSA | B10: 150 | C10: 150 | D10: 150 | E10: 150 | F10: 150 | G10: 150 | H10: 150 | I10: 150 | J10: 150 | K10: 150 | L10: 150
A12: Physician Adoption (Cumulative Users)
A13: Active Physicians on Platform | B13: 0 | C13: 2000 | D13: 5000 | E13: 15000 | F13: 35000 | G13: 80000 | H13: 100000 | I13: 120000 | J13: 140000 | K13: 160000 | L13: 200000
A14: Premium Conversion Rate | B14: 0 | C14: 0 | D14: 0.35 | E14: 0.33 | F14: 0.25 | G14: 0.22 | H14: 0.2 | I14: 0.18 | J14: 0.18 | K14: 0.18 | L14: 0.18
A15: Premium Physicians (calculated) | B15: =B13*B14 -> 0 | C15: =C13*C14 -> 0 | D15: =D13*D14 -> 1750 | E15: =E13*E14 -> 4950 | F15: =F13*F14 -> 8750 | G15: =G13*G14 -> 17600 | H15: =H13*H14 -> 20000 | I15: =I13*I14 -> 21600 | ... L15: =L13*L14 -> 36000
A17: Hospital Adoption
A18: Hospital Contracts (Cumulative) | B18: 0 | C18: 3 | D18: 10 | E18: 25 | F18: 50 | G18: 100 | H18: 120 | I18: 150 | J18: 170 | K18: 185 | L18: 200
A19: Enterprise Contracts (MOH-level) | B19: 0 | C19: 0 | D19: 0 | E19: 1 | F19: 1 | G19: 2 | H19: 2 | I19: 3 | J19: 3 | K19: 4 | L19: 5
A21: Pricing Assumptions (Annual)
A22: Individual Premium ($/yr) | B22: 348 | C22: 348 | D22: 348 | E22: 348 | F22: 348 | G22: 348 | H22: 348 | I22: 348 | J22: 348 | K22: 348 | L22: 348
A23: Hospital Avg ACV ($K/yr) | B23: 150 | C23: 150 | D23: 150 | E23: 150 | F23: 150 | G23: 150 | H23: 150 | I23: 150 | J23: 150 | K23: 150 | L23: 150
A24: Enterprise Avg ACV ($M/yr) | B24: 3 | C24: 3 | D24: 3 | E24: 3 | F24: 3 | G24: 3 | H24: 3 | I24: 3 | J24: 3 | K24: 3 | L24: 3
A25: BLS Course ($/participant) | B25: 200 | C25: 200 | D25: 200 | E25: 200 | F25: 200 | G25: 200 | H25: 200 | I25: 200 | J25: 200 | K25: 200 | L25: 200
A26: ACLS Course ($/participant) | B26: 350 | C26: 350 | D26: 350 | E26: 350 | F26: 350 | G26: 350 | H26: 350 | I26: 350 | J26: 350 | K26: 350 | L26: 350
A27: ATLS Course ($/participant) | B27: 500 | C27: 500 | D27: 500 | E27: 500 | F27: 500 | G27: 500 | H27: 500 | I27: 500 | J27: 500 | K27: 500 | L27: 500
A28: CME Subscription ($/yr) | B28: 99 | C28: 99 | D28: 99 | E28: 99 | F28: 99 | G28: 99 | H28: 99 | I28: 99 | J28: 99 | K28: 99 | L28: 99
A29: Institutional CME Contract ($/yr) | B29: 60000 | C29: 60000 | D29: 60000 | E29: 60000 | F29: 60000 | G29: 60000 | H29: 60000 | I29: 60000 | J29: 60000 | K29: 60000 | L29: 60000
A30: Trial Site Mgmt Avg ($/site) | B30: 10000 | C30: 10000 | D30: 10000 | E30: 10000 | F30: 10000 | G30: 10000 | H30: 10000 | I30: 10000 | J30: 10000 | K30: 10000 | L30: 10000
A31: Trial Data Mgmt Avg ($/patient) | B31: 5000 | C31: 5000 | D31: 5000 | E31: 5000 | F31: 5000 | G31: 5000 | H31: 5000 | I31: 5000 | J31: 5000 | K31: 5000 | L31: 5000
A32: RWD License Avg ($/dataset) | B32: 100000 | C32: 100000 | D32: 100000 | E32: 100000 | F32: 100000 | G32: 100000 | H32: 100000 | I32: 100000 | J32: 100000 | K32: 100000 | L32: 100000
A33: Registry Avg ($/yr) | B33: 200000 | C33: 200000 | D33: 200000 | E33: 200000 | F33: 200000 | G33: 200000 | H33: 200000 | I33: 200000 | J33: 200000 | K33: 200000 | L33: 200000
... A43: Gov Partnership Avg ($/yr) | B43: 2000000 | C43: 2000000 | D43: 2000000 | E43: 2000000 | F43: 2000000 | G43: 2000000 | H43: 2000000 | I43: 2000000 | J43: 2000000 | K43: 2000000 | L43: 2000000
A45: Volume Assumptions (Annual)
A46: BLS Participants | B46: 0 | C46: 7000 | D46: 8500 | E46: 9500 | F46: 9800 | G46: 10000 | H46: 11000 | I46: 12000 | J46: 13000 | K46: 14000 | L46: 15000
A47: ACLS Participants | B47: 0 | C47: 3500 | D47: 4200 | E47: 4800 | F47: 4900 | G47: 5000 | H47: 5500 | I47: 6000 | J47: 6500 | K47: 7000 | L47: 7500
A48: ATLS Participants | B48: 0 | C48: 1400 | D48: 1700 | E48: 1900 | F48: 1950 | G48: 2000 | H48: 2200 | I48: 2400 | J48: 2600 | K48: 2800 | L48: 3000
A49: CME Subscribers | B49: 0 | C49: 10000 | D49: 18000 | E49: 25000 | F49: 28000 | G49: 30000 | H49: 38000 | I49: 45000 | J49: 52000 | K49: 60000 | L49: 70000
A50: Institutional CME Contracts | B50: 0 | C50: 18 | D50: 30 | E50: 40 | F50: 45 | G50: 50 | H50: 55 | I50: 60 | J50: 65 | K50: 70 | L50: 75
A51: Trial Sites (active) | B51: 0 | C51: 0 | D51: 0 | E51: 20 | F51: 35 | G51: 40 | H51: 50 | I51: 60 | J51: 70 | K51: 80 | L51: 90
A52: Trial Patients (annual) | B52: 0 | C52: 0 | D52: 0 | E52: 600 | F52: 1500 | G52: 2000 | H52: 2800 | I52: 3500 | J52: 4000 | K52: 4500 | L52: 5000
A53: RWD Datasets Licensed | B53: 0 | C53: 0 | D53: 0 | E53: 5 | F53: 8 | G53: 10 | H53: 14 | I53: 18 | J53: 22 | K53: 26 | L53: 30
...

Sheet 2. Revenue
A1: REVENUE MODEL — 6 STREAMS ($M)
A2: Revenue Stream | B2: Year 0 | C2: Year 1 | D2: Year 2 | E2: Year 3 | F2: Year 4 | G2: Year 5 | H2: Year 6 | I2: Year 7 | J2: Year 8 | K2: Year 9 | L2: Year 10
A3: Stream 1 — SaaS Platform (SCII)
A4: Individual Premium Revenue | B4: ='1. Assumptions'!B15*'1. Assumptions'!B22/1000000 -> 0 | C4: ='1. Assumptions'!C15*'1. Assumptions'!C22/1000000 -> 0 | D4: ='1. Assumptions'!D15*'1. Assumptions'!D22/1000000 -> 0.609 | E4: ='1. Assumptions'!E15*'1. Assumptions'!E22/1000000 -> 1.7226 | F4: ='1. Assumptions'!F15*'1. Assumptions'!F22/1000000 -> 3.045 | G4: ='1. Assumptions'!G15*'1. Assumptions'!G22/1000000 -> 6.1248 | H4: ='1. Assumptions'!H15*'1. Assumptions'!H22/1000000 -> 6.96 | I4: ='1. Assumptions'!I15*'1. Assumptions'!I22/1000000 -> 7.5168 | ... L4: ='1. Assumptions'!L15*'1. Assumptions'!L22/1000000 -> 12.528
A5: Hospital Contracts Revenue | B5: ='1. Assumptions'!B18*'1. Assumptions'!B23*1000/1000000 -> 0 | C5: ='1. Assumptions'!C18*'1. Assumptions'!C23*1000/1000000 -> 0.45 | D5: ='1. Assumptions'!D18*'1. Assumptions'!D23*1000/1000000 -> 1.5 | E5: ='1. Assumptions'!E18*'1. Assumptions'!E23*1000/1000000 -> 3.75 | F5: ='1. Assumptions'!F18*'1. Assumptions'!F23*1000/1000000 -> 7.5 | G5: ='1. Assumptions'!G18*'1. Assumptions'!G23*1000/1000000 -> 15 | H5: ='1. Assumptions'!H18*'1. Assumptions'!H23*1000/1000000 -> 18 | I5: ='1. Assumptions'!I18*'1. Assumptions'!I23*1000/1000000 -> 22.5 | ... L5: ='1. Assumptions'!L18*'1. Assumptions'!L23*1000/1000000 -> 30
A6: Enterprise (MOH) Revenue | B6: ='1. Assumptions'!B19*'1. Assumptions'!B24 -> 0 | C6: ='1. Assumptions'!C19*'1. Assumptions'!C24 -> 0 | D6: ='1. Assumptions'!D19*'1. Assumptions'!D24 -> 0 | E6: ='1. Assumptions'!E19*'1. Assumptions'!E24 -> 3 | F6: ='1. Assumptions'!F19*'1. Assumptions'!F24 -> 3 | G6: ='1. Assumptions'!G19*'1. Assumptions'!G24 -> 6 | H6: ='1. Assumptions'!H19*'1. Assumptions'!H24 -> 6 | I6: ='1. Assumptions'!I19*'1. Assumptions'!I24 -> 9 | ... L6: ='1. Assumptions'!L19*'1. Assumptions'!L24 -> 15
A7: STREAM 1 TOTAL — SaaS | B7: =SUM(B4:B6) -> 0 | C7: =SUM(C4:C6) -> 0.45 | D7: =SUM(D4:D6) -> 2.109 | E7: =SUM(E4:E6) -> 8.4726 | F7: =SUM(F4:F6) -> 13.545 | G7: =SUM(G4:G6) -> 27.1248 | H7: =SUM(H4:H6) -> 30.96 | I7: =SUM(I4:I6) -> 39.0168 | ... L7: =SUM(L4:L6) -> 57.528
A9: Stream 2 — Medical Education (NAMA Knowledge)
A10: BLS Revenue | B10: ='1. Assumptions'!B46*'1. Assumptions'!B25/1000000 -> 0 | C10: ='1. Assumptions'!C46*'1. Assumptions'!C25/1000000 -> 1.4 | D10: ='1. Assumptions'!D46*'1. Assumptions'!D25/1000000 -> 1.7 | E10: ='1. Assumptions'!E46*'1. Assumptions'!E25/1000000 -> 1.9 | F10: ='1. Assumptions'!F46*'1. Assumptions'!F25/1000000 -> 1.96 | G10: ='1. Assumptions'!G46*'1. Assumptions'!G25/1000000 -> 2 | H10: ='1. Assumptions'!H46*'1. Assumptions'!H25/1000000 -> 2.2 | I10: ='1. Assumptions'!I46*'1. Assumptions'!I25/1000000 -> 2.4 | ... L10: ='1. Assumptions'!L46*'1. Assumptions'!L25/1000000 -> 3
A11: ACLS Revenue | B11: ='1. Assumptions'!B47*'1. Assumptions'!B26/1000000 -> 0 | C11: ='1. Assumptions'!C47*'1. Assumptions'!C26/1000000 -> 1.225 | D11: ='1. Assumptions'!D47*'1. Assumptions'!D26/1000000 -> 1.47 | E11: ='1. Assumptions'!E47*'1. Assumptions'!E26/1000000 -> 1.68 | F11: ='1. Assumptions'!F47*'1. Assumptions'!F26/1000000 -> 1.715 | G11: ='1. Assumptions'!G47*'1. Assumptions'!G26/1000000 -> 1.75 | H11: ='1. Assumptions'!H47*'1. Assumptions'!H26/1000000 -> 1.925 | I11: ='1. Assumptions'!I47*'1. Assumptions'!I26/1000000 -> 2.1 | ... L11: ='1. Assumptions'!L47*'1. Assumptions'!L26/1000000 -> 2.625
A12: ATLS Revenue | B12: ='1. Assumptions'!B48*'1. Assumptions'!B27/1000000 -> 0 | C12: ='1. Assumptions'!C48*'1. Assumptions'!C27/1000000 -> 0.7 | D12: ='1. Assumptions'!D48*'1. Assumptions'!D27/1000000 -> 0.85 | E12: ='1. Assumptions'!E48*'1. Assumptions'!E27/1000000 -> 0.95 | F12: ='1. Assumptions'!F48*'1. Assumptions'!F27/1000000 -> 0.975 | G12: ='1. Assumptions'!G48*'1. Assumptions'!G27/1000000 -> 1 | H12: ='1. Assumptions'!H48*'1. Assumptions'!H27/1000000 -> 1.1 | I12: ='1. Assumptions'!I48*'1. Assumptions'!I27/1000000 -> 1.2 | ... L12: ='1. Assumptions'!L48*'1. Assumptions'!L27/1000000 -> 1.5
A13: CME Subscription Revenue | B13: ='1. Assumptions'!B49*'1. Assumptions'!B28/1000000 -> 0 | C13: ='1. Assumptions'!C49*'1. Assumptions'!C28/1000000 -> 0.99 | D13: ='1. Assumptions'!D49*'1. Assumptions'!D28/1000000 -> 1.782 | E13: ='1. Assumptions'!E49*'1. Assumptions'!E28/1000000 -> 2.475 | F13: ='1. Assumptions'!F49*'1. Assumptions'!F28/1000000 -> 2.772 | G13: ='1. Assumptions'!G49*'1. Assumptions'!G28/1000000 -> 2.97 | H13: ='1. Assumptions'!H49*'1. Assumptions'!H28/1000000 -> 3.762 | I13: ='1. Assumptions'!I49*'1. Assumptions'!I28/1000000 -> 4.455 | ... L13: ='1. Assumptions'!L49*'1. Assumptions'!L28/1000000 -> 6.93
A14: Institutional CME Revenue | B14: ='1. Assumptions'!B50*'1. Assumptions'!B29/1000000 -> 0 | C14: ='1. Assumptions'!C50*'1. Assumptions'!C29/1000000 -> 1.08 | D14: ='1. Assumptions'!D50*'1. Assumptions'!D29/1000000 -> 1.8 | E14: ='1. Assumptions'!E50*'1. Assumptions'!E29/1000000 -> 2.4 | F14: ='1. Assumptions'!F50*'1. Assumptions'!F29/1000000 -> 2.7 | G14: ='1. Assumptions'!G50*'1. Assumptions'!G29/1000000 -> 3 | H14: ='1. Assumptions'!H50*'1. Assumptions'!H29/1000000 -> 3.3 | I14: ='1. Assumptions'!I50*'1. Assumptions'!I29/1000000 -> 3.6 | ... L14: ='1. Assumptions'!L50*'1. Assumptions'!L29/1000000 -> 4.5
A15: STREAM 2 TOTAL — CME | B15: =SUM(B10:B14) -> 0 | C15: =SUM(C10:C14) -> 5.395 | D15: =SUM(D10:D14) -> 7.602 | E15: =SUM(E10:E14) -> 9.405 | F15: =SUM(F10:F14) -> 10.122 | G15: =SUM(G10:G14) -> 10.72 | H15: =SUM(H10:H14) -> 12.287 | I15: =SUM(I10:I14) -> 13.755 | ... L15: =SUM(L10:L14) -> 18.555
A17: Stream 3 — Clinical Trials (NAMA Medical)
A18: Site Management Revenue | B18: ='1. Assumptions'!B51*'1. Assumptions'!B30/1000000 -> 0 | C18: ='1. Assumptions'!C51*'1. Assumptions'!C30/1000000 -> 0 | D18: ='1. Assumptions'!D51*'1. Assumptions'!D30/1000000 -> 0 | E18: ='1. Assumptions'!E51*'1. Assumptions'!E30/1000000 -> 0.2 | F18: ='1. Assumptions'!F51*'1. Assumptions'!F30/1000000 -> 0.35 | G18: ='1. Assumptions'!G51*'1. Assumptions'!G30/1000000 -> 0.4 | H18: ='1. Assumptions'!H51*'1. Assumptions'!H30/1000000 -> 0.5 | I18: ='1. Assumptions'!I51*'1. Assumptions'!I30/1000000 -> 0.6 | ... L18: ='1. Assumptions'!L51*'1. Assumptions'!L30/1000000 -> 0.9
A19: Data Management Revenue | B19: ='1. Assumptions'!B52*'1. Assumptions'!B31/1000000 -> 0 | C19: ='1. Assumptions'!C52*'1. Assumptions'!C31/1000000 -> 0 | D19: ='1. Assumptions'!D52*'1. Assumptions'!D31/1000000 -> 0 | E19: ='1. Assumptions'!E52*'1. Assumptions'!E31/1000000 -> 3 | F19: ='1. Assumptions'!F52*'1. Assumptions'!F31/1000000 -> 7.5 | G19: ='1. Assumptions'!G52*'1. Assumptions'!G31/1000000 -> 10 | H19: ='1. Assumptions'!H52*'1. Assumptions'!H31/1000000 -> 14 | I19: ='1. Assumptions'!I52*'1. Assumptions'!I31/1000000 -> 17.5 | ... L19: ='1. Assumptions'!L52*'1. Assumptions'!L31/1000000 -> 25
A20: RWD Licensing Revenue | B20: ='1. Assumptions'!B53*'1. Assumptions'!B32/1000000 -> 0 | C20: ='1. Assumptions'!C53*'1. Assumptions'!C32/1000000 -> 0 | D20: ='1. Assumptions'!D53*'1. Assumptions'!D32/1000000 -> 0 | E20: ='1. Assumptions'!E53*'1. Assumptions'!E32/1000000 -> 0.5 | F20: ='1. Assumptions'!F53*'1. Assumptions'!F32/1000000 -> 0.8 | G20: ='1. Assumptions'!G53*'1. Assumptions'!G32/1000000 -> 1 | H20: ='1. Assumptions'!H53*'1. Assumptions'!H32/1000000 -> 1.4 | I20: ='1. Assumptions'!I53*'1. Assumptions'!I32/1000000 -> 1.8 | ... L20: ='1. Assumptions'!L53*'1. Assumptions'!L32/1000000 -> 3
A21: Registry Services Revenue | B21: ='1. Assumptions'!B54*'1. Assumptions'!B33/1000000 -> 0 | C21: ='1. Assumptions'!C54*'1. Assumptions'!C33/1000000 -> 0 | D21: ='1. Assumptions'!D54*'1. Assumptions'!D33/1000000 -> 0 | E21: ='1. Assumptions'!E54*'1. Assumptions'!E33/1000000 -> 0.6 | F21: ='1. Assumptions'!F54*'1. Assumptions'!F33/1000000 -> 0.8 | G21: ='1. Assumptions'!G54*'1. Assumptions'!G33/1000000 -> 1 | H21: ='1. Assumptions'!H54*'1. Assumptions'!H33/1000000 -> 1.2 | I21: ='1. Assumptions'!I54*'1. Assumptions'!I33/1000000 -> 1.4 | ... L21: ='1. Assumptions'!L54*'1. Assumptions'!L33/1000000 -> 2
A22: STREAM 3 TOTAL — Trials | B22: =SUM(B18:B21) -> 0 | C22: =SUM(C18:C21) -> 0 | D22: =SUM(D18:D21) -> 0 | E22: =SUM(E18:E21) -> 4.3 | F22: =SUM(F18:F21) -> 9.45 | G22: =SUM(G18:G21) -> 12.4 | H22: =SUM(H18:H21) -> 17.1 | I22: =SUM(I18:I21) -> 21.3 | ... L22: =SUM(L18:L21) -> 30.9
A24: Stream 4 — Scientific Publishing (WARAQA)
A25: Article Processing Revenue | B25: ='1. Assumptions'!B55*'1. Assumptions'!B34/1000000 -> 0 | C25: ='1. Assumptions'!C55*'1. Assumptions'!C34/1000000 -> 0 | D25: ='1. Assumptions'!D55*'1. Assumptions'!D34/1000000 -> 0.3 | E25: ='1. Assumptions'!E55*'1. Assumptions'!E34/1000000 -> 0.7 | F25: ='1. Assumptions'!F55*'1. Assumptions'!F34/1000000 -> 0.9 | G25: ='1. Assumptions'!G55*'1. Assumptions'!G34/1000000 -> 1 | H25: ='1. Assumptions'!H55*'1. Assumptions'!H34/1000000 -> 1.2 | I25: ='1. Assumptions'!I55*'1. Assumptions'!I34/1000000 -> 1.4 | ... L25: ='1. Assumptions'!L55*'1. Assumptions'!L34/1000000 -> 2
A26: Systematic Reviews Revenue | B26: ='1. Assumptions'!B56*'1. Assumptions'!B35/1000000 -> 0 | C26: ='1. Assumptions'!C56*'1. Assumptions'!C35/1000000 -> 0 | D26: ='1. Assumptions'!D56*'1. Assumptions'!D35/1000000 -> 0.24 | E26: ='1. Assumptions'!E56*'1. Assumptions'!E35/1000000 -> 0.6 | F26: ='1. Assumptions'!F56*'1. Assumptions'!F35/1000000 -> 0.75 | G26: ='1. Assumptions'!G56*'1. Assumptions'!G35/1000000 -> 0.9 | H26: ='1. Assumptions'!H56*'1. Assumptions'!H35/1000000 -> 1.05 | I26: ='1. Assumptions'!I56*'1. Assumptions'!I35/1000000 -> 1.2 | ... L26: ='1. Assumptions'!L56*'1. Assumptions'!L35/1000000 -> 1.65
A27: Guideline Development Revenue | B27: ='1. Assumptions'!B57*'1. Assumptions'!B36/1000000 -> 0 | C27: ='1. Assumptions'!C57*'1. Assumptions'!C36/1000000 -> 0 | D27: ='1. Assumptions'!D57*'1. Assumptions'!D36/1000000 -> 0.3 | E27: ='1. Assumptions'!E57*'1. Assumptions'!E36/1000000 -> 0.7 | F27: ='1. Assumptions'!F57*'1. Assumptions'!F36/1000000 -> 0.9 | G27: ='1. Assumptions'!G57*'1. Assumptions'!G36/1000000 -> 1 | H27: ='1. Assumptions'!H57*'1. Assumptions'!H36/1000000 -> 1.2 | I27: ='1. Assumptions'!I57*'1. Assumptions'!I36/1000000 -> 1.4 | ... L27: ='1. Assumptions'!L57*'1. Assumptions'!L36/1000000 -> 2
A28: Journal Subscriptions Revenue | B28: ='1. Assumptions'!B58*'1. Assumptions'!B37/1000000 -> 0 | C28: ='1. Assumptions'!C58*'1. Assumptions'!C37/1000000 -> 0 | D28: ='1. Assumptions'!D58*'1. Assumptions'!D37/1000000 -> 0.03 | E28: ='1. Assumptions'!E58*'1. Assumptions'!E37/1000000 -> 0.06 | F28: ='1. Assumptions'!F58*'1. Assumptions'!F37/1000000 -> 0.08 | G28: ='1. Assumptions'!G58*'1. Assumptions'!G37/1000000 -> 0.1 | H28: ='1. Assumptions'!H58*'1. Assumptions'!H37/1000000 -> 0.12 | I28: ='1. Assumptions'!I58*'1. Assumptions'!I37/1000000 -> 0.14 | ... L28: ='1. Assumptions'!L58*'1. Assumptions'!L37/1000000 -> 0.2
A29: STREAM 4 TOTAL — Publishing | B29: =SUM(B25:B28) -> 0 | C29: =SUM(C25:C28) -> 0 | D29: =SUM(D25:D28) -> 0.87 | E29: =SUM(E25:E28) -> 2.06 | F29: =SUM(F25:F28) -> 2.63 | G29: =SUM(G25:G28) -> 3 | H29: =SUM(H25:H28) -> 3.57 | I29: =SUM(I25:I28) -> 4.14 | ... L29: =SUM(L25:L28) -> 5.85
A31: Stream 5 — Bioequivalence (NAMA Bio)
A32: BE Studies Revenue | B32: ='1. Assumptions'!B59*'1. Assumptions'!B38/1000000 -> 0 | C32: ='1. Assumptions'!C59*'1. Assumptions'!C38/1000000 -> 0 | D32: ='1. Assumptions'!D59*'1. Assumptions'!D38/1000000 -> 0 | E32: ='1. Assumptions'!E59*'1. Assumptions'!E38/1000000 -> 0 | F32: ='1. Assumptions'!F59*'1. Assumptions'!F38/1000000 -> 3.6 | G32: ='1. Assumptions'!G59*'1. Assumptions'!G38/1000000 -> 6 | H32: ='1. Assumptions'!H59*'1. Assumptions'!H38/1000000 -> 7.5 | I32: ='1. Assumptions'!I59*'1. Assumptions'!I38/1000000 -> 9 | ... L32: ='1. Assumptions'!L59*'1. Assumptions'!L38/1000000 -> 13.5
A33: Regulatory Support Revenue | B33: ='1. Assumptions'!B60*'1. Assumptions'!B39/1000000 -> 0 | C33: ='1. Assumptions'!C60*'1. Assumptions'!C39/1000000 -> 0 | D33: ='1. Assumptions'!D60*'1. Assumptions'!D39/1000000 -> 0 | E33: ='1. Assumptions'!E60*'1. Assumptions'!E39/1000000 -> 0 | F33: ='1. Assumptions'!F60*'1. Assumptions'!F39/1000000 -> 1.8 | G33: ='1. Assumptions'!G60*'1. Assumptions'!G39/1000000 -> 3 | H33: ='1. Assumptions'!H60*'1. Assumptions'!H39/1000000 -> 3.5 | I33: ='1. Assumptions'!I60*'1. Assumptions'!I39/1000000 -> 4 | ... L33: ='1. Assumptions'!L60*'1. Assumptions'!L39/1000000 -> 5.5
A34: Pharmacovigilance Revenue | B34: ='1. Assumptions'!B61*'1. Assumptions'!B40/1000000 -> 0 | C34: ='1. Assumptions'!C61*'1. Assumptions'!C40/1000000 -> 0 | D34: ='1. Assumptions'!D61*'1. Assumptions'!D40/1000000 -> 0 | E34: ='1. Assumptions'!E61*'1. Assumptions'!E40/1000000 -> 0 | F34: ='1. Assumptions'!F61*'1. Assumptions'!F40/1000000 -> 1.5 | G34: ='1. Assumptions'!G61*'1. Assumptions'!G40/1000000 -> 2.4 | H34: ='1. Assumptions'!H61*'1. Assumptions'!H40/1000000 -> 3 | I34: ='1. Assumptions'!I61*'1. Assumptions'!I40/1000000 -> 3.6 | ... L34: ='1. Assumptions'!L61*'1. Assumptions'!L40/1000000 -> 5.4
A35: STREAM 5 TOTAL — Bioequivalence | B35: =SUM(B32:B34) -> 0 | C35: =SUM(C32:C34) -> 0 | D35: =SUM(D32:D34) -> 0 | E35: =SUM(E32:E34) -> 0 | F35: =SUM(F32:F34) -> 6.9 | G35: =SUM(G32:G34) -> 11.4 | H35: =SUM(H32:H34) -> 14 | I35: =SUM(I32:I34) -> 16.6 | ... L35: =SUM(L32:L34) -> 24.4
A37: Stream 6 — Data Licensing & Analytics
A38: API Licensing Revenue | B38: ='1. Assumptions'!B62*'1. Assumptions'!B41/1000000 -> 0 | C38: ='1. Assumptions'!C62*'1. Assumptions'!C41/1000000 -> 0 | D38: ='1. Assumptions'!D62*'1. Assumptions'!D41/1000000 -> 0 | E38: ='1. Assumptions'!E62*'1. Assumptions'!E41/1000000 -> 0 | F38: ='1. Assumptions'!F62*'1. Assumptions'!F41/1000000 -> 1.8 | G38: ='1. Assumptions'!G62*'1. Assumptions'!G41/1000000 -> 3 | H38: ='1. Assumptions'!H62*'1. Assumptions'!H41/1000000 -> 4.2 | I38: ='1. Assumptions'!I62*'1. Assumptions'!I41/1000000 -> 5.4 | ... L38: ='1. Assumptions'!L62*'1. Assumptions'!L41/1000000 -> 9
A39: Custom Reports Revenue | B39: ='1. Assumptions'!B63*'1. Assumptions'!B42/1000000 -> 0 | C39: ='1. Assumptions'!C63*'1. Assumptions'!C42/1000000 -> 0 | D39: ='1. Assumptions'!D63*'1. Assumptions'!D42/1000000 -> 0 | E39: ='1. Assumptions'!E63*'1. Assumptions'!E42/1000000 -> 0 | F39: ='1. Assumptions'!F63*'1. Assumptions'!F42/1000000 -> 1.25 | G39: ='1. Assumptions'!G63*'1. Assumptions'!G42/1000000 -> 2 | H39: ='1. Assumptions'!H63*'1. Assumptions'!H42/1000000 -> 2.75 | I39: ='1. Assumptions'!I63*'1. Assumptions'!I42/1000000 -> 3.5 | ... L39: ='1. Assumptions'!L63*'1. Assumptions'!L42/1000000 -> 5.75
A40: Government Partnerships Revenue | B40: ='1. Assumptions'!B64*'1. Assumptions'!B43/1000000 -> 0 | C40: ='1. Assumptions'!C64*'1. Assumptions'!C43/1000000 -> 0 | D40: ='1. Assumptions'!D64*'1. Assumptions'!D43/1000000 -> 0 | E40: ='1. Assumptions'!E64*'1. Assumptions'!E43/1000000 -> 0 | F40: ='1. Assumptions'!F64*'1. Assumptions'!F43/1000000 -> 2 | G40: ='1. Assumptions'!G64*'1. Assumptions'!G43/1000000 -> 4 | H40: ='1. Assumptions'!H64*'1. Assumptions'!H43/1000000 -> 4 | I40: ='1. Assumptions'!I64*'1. Assumptions'!I43/1000000 -> 6 | ... L40: ='1. Assumptions'!L64*'1. Assumptions'!L43/1000000 -> 8
A41: STREAM 6 TOTAL — Data Licensing | B41: =SUM(B38:B40) -> 0 | C41: =SUM(C38:C40) -> 0 | D41: =SUM(D38:D40) -> 0 | E41: =SUM(E38:E40) -> 0 | F41: =SUM(F38:F40) -> 5.05 | G41: =SUM(G38:G40) -> 9 | H41: =SUM(H38:H40) -> 10.95 | I41: =SUM(I38:I40) -> 14.9 | ... L41: =SUM(L38:L40) -> 22.75
A43: CONSOLIDATED REVENUE
A44: TOTAL REVENUE ($M) | B44: =B7+B15+B22+B29+B35+B41 -> 0 | C44: =C7+C15+C22+C29+C35+C41 -> 5.845 | D44: =D7+D15+D22+D29+D35+D41 -> 10.581 | E44: =E7+E15+E22+E29+E35+E41 -> 24.2376 | F44: =F7+F15+F22+F29+F35+F41 -> 47.697 | G44: =G7+G15+G22+G29+G35+G41 -> 73.6448 | H44: =H7+H15+H22+H29+H35+H41 -> 88.867 | I44: =I7+I15+I22+I29+I35+I41 -> 109.7118 | ... L44: =L7+L15+L22+L29+L35+L41 -> 159.983
A45: YoY Revenue Growth (%) | B45: - | C45: - | D45: =IF(C44>0,(D44-C44)/C44,0) -> 0.81026518 | E45: =IF(D44>0,(E44-D44)/D44,0) -> 1.290672 | F45: =IF(E44>0,(F44-E44)/E44,0) -> 0.96789286 | G45: =IF(F44>0,(G44-F44)/F44,0) -> 0.54401325 | H45: =IF(G44>0,(H44-G44)/G44,0) -> 0.20669755 | I45: =IF(H44>0,(I44-H44)/H44,0) -> 0.23456176 | J45: =IF(I44>0,(J44-I44)/I44,0) -> 0.12797894 | K45: =IF(J44>0,(K44-J44)/J44,0) -> 0.14860132 | L45: =IF(K44>0,(L44-K44)/K44,0) -> 0.12551216
A47: REVENUE MIX (%)
...

Sheet 3. P&L
A1: INCOME STATEMENT ($M)
B2: Year 0 | C2: Year 1 | D2: Year 2 | E2: Year 3 | F2: Year 4 | G2: Year 5 | H2: Year 6 | I2: Year 7 | J2: Year 8 | K2: Year 9 | L2: Year 10
A3: Total Revenue | B3: ='2. Revenue'!B44 -> 0 | C3: ='2. Revenue'!C44 -> 5.845 | D3: ='2. Revenue'!D44 -> 10.581 | E3: ='2. Revenue'!E44 -> 24.2376 | F3: ='2. Revenue'!F44 -> 47.697 | G3: ='2. Revenue'!G44 -> 73.6448 | H3: ='2. Revenue'!H44 -> 88.867 | I3: ='2. Revenue'!I44 -> 109.7118 | ... L3: ='2. Revenue'!L44 -> 159.983
A4: Cost of Revenue
A5: Personnel | B5: ='1. Assumptions'!B67*'1. Assumptions'!B68/1000 -> 0 | C5: ='1. Assumptions'!C67*'1. Assumptions'!C68/1000 -> 1.5 | D5: ='1. Assumptions'!D67*'1. Assumptions'!D68/1000 -> 2.5 | E5: ='1. Assumptions'!E67*'1. Assumptions'!E68/1000 -> 4.725 | F5: ='1. Assumptions'!F67*'1. Assumptions'!F68/1000 -> 6.6 | G5: ='1. Assumptions'!G67*'1. Assumptions'!G68/1000 -> 9.2 | H5: ='1. Assumptions'!H67*'1. Assumptions'!H68/1000 -> 11.21 | I5: ='1. Assumptions'!I67*'1. Assumptions'!I68/1000 -> 14.4 | ... L5: ='1. Assumptions'!L67*'1. Assumptions'!L68/1000 -> 23.04
A6: Technology Infrastructure | B6: =B3*'1. Assumptions'!B69 -> 0 | C6: =C3*'1. Assumptions'!C69 -> 0.7014 | D6: =D3*'1. Assumptions'!D69 -> 1.0581 | E6: =E3*'1. Assumptions'!E69 -> 2.181384 | F6: =F3*'1. Assumptions'!F69 -> 3.81576 | G6: =G3*'1. Assumptions'!G69 -> 5.155136 | H6: =H3*'1. Assumptions'!H69 -> 5.33202 | I6: =I3*'1. Assumptions'!I69 -> 6.582708 | ... L6: =L3*'1. Assumptions'!L69 -> 7.99915
A7: Content Creation | B7: =B3*'1. Assumptions'!B71 -> 0 | C7: =C3*'1. Assumptions'!C71 -> 0.52605 | D7: =D3*'1. Assumptions'!D71 -> 0.74067 | E7: =E3*'1. Assumptions'!E71 -> 1.454256 | F7: =F3*'1. Assumptions'!F71 -> 2.38485 | G7: =G3*'1. Assumptions'!G71 -> 2.945792 | H7: =H3*'1. Assumptions'!H71 -> 3.55468 | I7: =I3*'1. Assumptions'!I71 -> 3.291354 | ... L7: =L3*'1. Assumptions'!L71 -> 4.79949
A8: Sales & Marketing | B8: =B3*'1. Assumptions'!B70 -> 0 | C8: =C3*'1. Assumptions'!C70 -> 0.4676 | D8: =D3*'1. Assumptions'!D70 -> 0.63486 | E8: =E3*'1. Assumptions'!E70 -> 1.21188 | F8: =F3*'1. Assumptions'!F70 -> 1.90788 | G8: =G3*'1. Assumptions'!G70 -> 2.209344 | H8: =H3*'1. Assumptions'!H70 -> 2.66601 | I8: =I3*'1. Assumptions'!I70 -> 2.194236 | ... L8: =L3*'1. Assumptions'!L70 -> 3.19966
A9: Regulatory & Compliance | B9: ='1. Assumptions'!B72 -> 0 | C9: ='1. Assumptions'!C72 -> 0.3 | D9: ='1. Assumptions'!D72 -> 0.5 | E9: ='1. Assumptions'!E72 -> 0.8 | F9: ='1. Assumptions'!F72 -> 1 | G9: ='1. Assumptions'!G72 -> 1.2 | H9: ='1. Assumptions'!H72 -> 1.3 | I9: ='1. Assumptions'!I72 -> 1.5 | ... L9: ='1. Assumptions'!L72 -> 1.8
A10: G&A | B10: =B3*'1. Assumptions'!B73 -> 0 | C10: =C3*'1. Assumptions'!C73 -> 0.2338 | D10: =D3*'1. Assumptions'!D73 -> 0.31743 | E10: =E3*'1. Assumptions'!E73 -> 0.727128 | F10: =F3*'1. Assumptions'!F73 -> 0.95394 | G10: =G3*'1. Assumptions'!G73 -> 1.472896 | H10: =H3*'1. Assumptions'!H73 -> 1.77734 | I10: =I3*'1. Assumptions'!I73 -> 1.097118 | ... L10: =L3*'1. Assumptions'!L73 -> 1.59983
A11: Clinical Trial COGS | B11: ='2. Revenue'!B22*'1. Assumptions'!B74 -> 0 | C11: ='2. Revenue'!C22*'1. Assumptions'!C74 -> 0 | D11: ='2. Revenue'!D22*'1. Assumptions'!D74 -> 0 | E11: ='2. Revenue'!E22*'1. Assumptions'!E74 -> 1.935 | F11: ='2. Revenue'!F22*'1. Assumptions'!F74 -> 3.78 | G11: ='2. Revenue'!G22*'1. Assumptions'!G74 -> 4.712 | H11: ='2. Revenue'!H22*'1. Assumptions'!H74 -> 6.156 | I11: ='2. Revenue'!I22*'1. Assumptions'!I74 -> 7.242 | ... L11: ='2. Revenue'!L22*'1. Assumptions'!L74 -> 8.652
A12: Bioequivalence COGS | B12: ='2. Revenue'!B35*'1. Assumptions'!B75 -> 0 | C12: ='2. Revenue'!C35*'1. Assumptions'!C75 -> 0 | D12: ='2. Revenue'!D35*'1. Assumptions'!D75 -> 0 | E12: ='2. Revenue'!E35*'1. Assumptions'!E75 -> 0 | F12: ='2. Revenue'!F35*'1. Assumptions'!F75 -> 2.415 | G12: ='2. Revenue'!G35*'1. Assumptions'!G75 -> 3.648 | H12: ='2. Revenue'!H35*'1. Assumptions'!H75 -> 4.2 | I12: ='2. Revenue'!I35*'1. Assumptions'!I75 -> 4.648 | ... L12: ='2. Revenue'!L35*'1. Assumptions'!L75 -> 5.368
A13: Data Licensing COGS | B13: ='2. Revenue'!B41*'1. Assumptions'!B76 -> 0 | C13: ='2. Revenue'!C41*'1. Assumptions'!C76 -> 0 | D13: ='2. Revenue'!D41*'1. Assumptions'!D76 -> 0 | E13: ='2. Revenue'!E41*'1. Assumptions'!E76 -> 0 | F13: ='2. Revenue'!F41*'1. Assumptions'!F76 -> 0.909 | G13: ='2. Revenue'!G41*'1. Assumptions'!G76 -> 1.35 | H13: ='2. Revenue'!H41*'1. Assumptions'!H76 -> 1.4235 | I13: ='2. Revenue'!I41*'1. Assumptions'!I76 -> 1.788 | ... L13: ='2. Revenue'!L41*'1. Assumptions'!L76 -> 1.82
A14: TOTAL COGS | B14: =SUM(B5:B13) -> 0 | C14: =SUM(C5:C13) -> 3.72885 | D14: =SUM(D5:D13) -> 5.75106 | E14: =SUM(E5:E13) -> 13.034648 | F14: =SUM(F5:F13) -> 23.76643 | G14: =SUM(G5:G13) -> 31.893168 | H14: =SUM(H5:H13) -> 37.61955 | I14: =SUM(I5:I13) -> 42.743416 | ... L14: =SUM(L5:L13) -> 58.27813
A16: GROSS PROFIT | B16: =B3-B14 -> 0 | C16: =C3-C14 -> 2.11615 | D16: =D3-D14 -> 4.82994 | E16: =E3-E14 -> 11.202952 | F16: =F3-F14 -> 23.93057 | G16: =G3-G14 -> 41.751632 | H16: =H3-H14 -> 51.24745 | I16: =I3-I14 -> 66.968384 | ... L16: =L3-L14 -> 101.70487
A17: Gross Margin % | B17: =IF(B3>0,B16/B3,0) -> 0 | C17: =IF(C3>0,C16/C3,0) -> 0.36204448 | D17: =IF(D3>0,D16/D3,0) -> 0.45647292 | E17: =IF(E3>0,E16/E3,0) -> 0.46221375 | F17: =IF(F3>0,F16/F3,0) -> 0.50172065 | G17: =IF(G3>0,G16/G3,0) -> 0.56693252 | H17: =IF(H3>0,H16/H3,0) -> 0.57667582 | I17: =IF(I3>0,I16/I3,0) -> 0.61040275 | ... L17: =IF(L3>0,L16/L3,0) -> 0.63572298
A19: EBITDA | B19: =B16 -> 0 | C19: =C16 -> 2.11615 | D19: =D16 -> 4.82994 | E19: =E16 -> 11.202952 | F19: =F16 -> 23.93057 | G19: =G16 -> 41.751632 | H19: =H16 -> 51.24745 | I19: =I16 -> 66.968384 | ... L19: =L16 -> 101.70487
A20: EBITDA Margin % | B20: =IF(B3>0,B19/B3,0) -> 0 | C20: =IF(C3>0,C19/C3,0) -> 0.36204448 | D20: =IF(D3>0,D19/D3,0) -> 0.45647292 | E20: =IF(E3>0,E19/E3,0) -> 0.46221375 | F20: =IF(F3>0,F19/F3,0) -> 0.50172065 | G20: =IF(G3>0,G19/G3,0) -> 0.56693252 | H20: =IF(H3>0,H19/H3,0) -> 0.57667582 | I20: =IF(I3>0,I19/I3,0) -> 0.61040275 | ... L20: =IF(L3>0,L19/L3,0) -> 0.63572298
A21: Depreciation & Amortization | B21: =B6*'1. Assumptions'!B94 -> 0 | C21: =C6*'1. Assumptions'!C94 -> 0.049098 | D21: =D6*'1. Assumptions'!D94 -> 0.074067 | E21: =E6*'1. Assumptions'!E94 -> 0.15269688 | F21: =F6*'1. Assumptions'!F94 -> 0.2671032 | G21: =G6*'1. Assumptions'!G94 -> 0.36085952 | H21: =H6*'1. Assumptions'!H94 -> 0.3732414 | I21: =I6*'1. Assumptions'!I94 -> 0.46078956 | ... L21: =L6*'1. Assumptions'!L94 -> 0.5599405
A22: EBIT | B22: =B19-B21 -> 0 | C22: =C19-C21 -> 2.067052 | D22: =D19-D21 -> 4.755873 | E22: =E19-E21 -> 11.050255 | F22: =F19-F21 -> 23.663467 | G22: =G19-G21 -> 41.390772 | H22: =H19-H21 -> 50.874209 | I22: =I19-I21 -> 66.507594 | ... L22: =L19-L21 -> 101.14493
A23: Income Tax | B23: =MAX(0,B22)*'1. Assumptions'!B93 -> 0 | C23: =MAX(0,C22)*'1. Assumptions'!C93 -> 0 | D23: =MAX(0,D22)*'1. Assumptions'!D93 -> 0 | E23: =MAX(0,E22)*'1. Assumptions'!E93 -> 0 | F23: =MAX(0,F22)*'1. Assumptions'!F93 -> 0 | G23: =MAX(0,G22)*'1. Assumptions'!G93 -> 0 | H23: =MAX(0,H22)*'1. Assumptions'!H93 -> 2.5437104 | I23: =MAX(0,I22)*'1. Assumptions'!I93 -> 6.6507594 | ... L23: =MAX(0,L22)*'1. Assumptions'!L93 -> 20.228986
A24: NET INCOME | B24: =B22-B23 -> 0 | C24: =C22-C23 -> 2.067052 | D24: =D22-D23 -> 4.755873 | E24: =E22-E23 -> 11.050255 | F24: =F22-F23 -> 23.663467 | G24: =G22-G23 -> 41.390772 | H24: =H22-H23 -> 48.330498 | I24: =I22-I23 -> 59.856835 | ... L24: =L22-L23 -> 80.915944
A25: Net Margin % | B25: =IF(B3>0,B24/B3,0) -> 0 | C25: =IF(C3>0,C24/C3,0) -> 0.35364448 | D25: =IF(D3>0,D24/D3,0) -> 0.44947292 | E25: =IF(E3>0,E24/E3,0) -> 0.45591375 | F25: =IF(F3>0,F24/F3,0) -> 0.49612065 | G25: =IF(G3>0,G24/G3,0) -> 0.56203252 | H25: =IF(H3>0,H24/H3,0) -> 0.54385203 | I25: =IF(I3>0,I24/I3,0) -> 0.54558247 | ... L25: =IF(L3>0,L24/L3,0) -> 0.50577839

Sheet 4. Unit Economics
A1: UNIT ECONOMICS BY SEGMENT
A2: Segment | B2: ACV ($) | C2: CAC ($) | D2: LTV ($) | E2: LTV:CAC | F2: Payback (mo) | G2: Churn
A3: Individual Premium | B3: 348 | C3: 50 | D3: 3480 | E3: =IF(C3>0,D3/C3,0) -> 69.6 | F3: =IF(B3>0,C3/B3*12,0) -> 1.7241379 | G3: 0.1
A4: Hospital | B4: 150000 | C4: 10000 | D4: 937500 | E4: =IF(C4>0,D4/C4,0) -> 93.75 | F4: =IF(B4>0,C4/B4*12,0) -> 0.8 | G4: 0.05
A5: Enterprise (MOH) | B5: 3000000 | C5: 100000 | D5: 56250000 | E5: =IF(C5>0,D5/C5,0) -> 562.5 | F5: =IF(B5>0,C5/B5*12,0) -> 0.4 | G5: 0.02
A6: CME Courses (avg) | B6: 300 | C6: 30 | D6: 3000 | E6: =IF(C6>0,D6/C6,0) -> 100 | F6: =IF(B6>0,C6/B6*12,0) -> 1.2 | G6: 0
A7: Clinical Trials (avg) | B7: 100000 | C7: 20000 | D7: 412500 | E7: =IF(C7>0,D7/C7,0) -> 20.625 | F7: =IF(B7>0,C7/B7*12,0) -> 2.4 | G7: 0.08
A10: CAC BY ACQUISITION CHANNEL
A11: Channel | B11: Cost/Lead ($) | C11: Conv. Rate | D11: CAC ($) | E11: Scale Target
A12: Organic (SEO/Content) | B12: 10 | C12: 0.05 | D12: =IF(C12>0,B12/C12,0) -> 200 | E12: $2M/yr investment
A13: Physician Events | B13: 50 | C13: 0.2 | D13: =IF(C13>0,B13/C13,0) -> 250 | E13: 40 events/yr
A14: Hospital Sales (Direct) | B14: 5000 | C14: 0.3 | D14: =IF(C14>0,B14/C14,0) -> 16666.667 | E14: 8 reps/yr
A15: Digital Marketing (SEM) | B15: 20 | C15: 0.03 | D15: =IF(C15>0,B15/C15,0) -> 666.66667 | E15: $1M/yr budget
A16: Partner Channel (SFDA) | B16: 0 | C16: 0.4 | D16: =IF(C16>0,B16/C16,0) -> 0 | E16: 2-3 partnerships

Sheet 5. Cash Flow
A1: CASH FLOW STATEMENT ($M)
B2: Year 0 | C2: Year 1 | D2: Year 2 | E2: Year 3 | F2: Year 4 | G2: Year 5 | H2: Year 6 | I2: Year 7 | J2: Year 8 | K2: Year 9 | L2: Year 10
A3: Operating Cash Flow
A4: Net Income | B4: ='3. P&L'!B24 -> 0 | C4: ='3. P&L'!C24 -> 2.067052 | D4: ='3. P&L'!D24 -> 4.755873 | E4: ='3. P&L'!E24 -> 11.050255 | F4: ='3. P&L'!F24 -> 23.663467 | G4: ='3. P&L'!G24 -> 41.390772 | H4: ='3. P&L'!H24 -> 48.330498 | I4: ='3. P&L'!I24 -> 59.856835 | ... L4: ='3. P&L'!L24 -> 80.915944
A5: Add: D&A | B5: ='3. P&L'!B21 -> 0 | C5: ='3. P&L'!C21 -> 0.049098 | D5: ='3. P&L'!D21 -> 0.074067 | E5: ='3. P&L'!E21 -> 0.15269688 | F5: ='3. P&L'!F21 -> 0.2671032 | G5: ='3. P&L'!G21 -> 0.36085952 | H5: ='3. P&L'!H21 -> 0.3732414 | I5: ='3. P&L'!I21 -> 0.46078956 | ... L5: ='3. P&L'!L21 -> 0.5599405
A6: Working Capital Changes | B6: =0 -> 0 | C6: =0 -> 0 | D6: =-0.05*('2. Revenue'!D44-'2. Revenue'!C44) -> -0.2368 | E6: =-0.05*('2. Revenue'!E44-'2. Revenue'!D44) -> -0.68283 | F6: =-0.05*('2. Revenue'!F44-'2. Revenue'!E44) -> -1.17297 | G6: =-0.05*('2. Revenue'!G44-'2. Revenue'!F44) -> -1.29739 | H6: =-0.05*('2. Revenue'!H44-'2. Revenue'!G44) -> -0.76111 | I6: =-0.05*('2. Revenue'!I44-'2. Revenue'!H44) -> -1.04224 | J6: =-0.05*('2. Revenue'!J44-'2. Revenue'!I44) -> -0.70204 | K6: =-0.05*('2. Revenue'!K44-'2. Revenue'!J44) -> -0.91949 | L6: =-0.05*('2. Revenue'!L44-'2. Revenue'!K44) -> -0.89203
A7: OPERATING CASH FLOW | B7: =B4+B5+B6 -> 0 | C7: =C4+C5+C6 -> 2.11615 | D7: =D4+D5+D6 -> 4.59314 | E7: =E4+E5+E6 -> 10.520122 | F7: =F4+F5+F6 -> 22.7576 | G7: =G4+G5+G6 -> 40.454242 | H7: =H4+H5+H6 -> 47.94263 | I7: =I4+I5+I6 -> 59.275385 | ... L7: =L4+L5+L6 -> 80.583854
A9: Investing Cash Flow
A10: Capex (Technology Development) | B10: 0 | C10: -1 | D10: -1.5 | E10: -3 | F10: -4 | G10: -5 | H10: -6 | I10: -7 | J10: -8 | K10: -9 | L10: -10
A11: INVESTING CASH FLOW | B11: =B10 -> 0 | C11: =C10 -> -1 | D11: =D10 -> -1.5 | E11: =E10 -> -3 | F11: =F10 -> -4 | G11: =G10 -> -5 | H11: =H10 -> -6 | I11: =I10 -> -7 | ... L11: =L10 -> -10
A13: Financing Cash Flow
A14: Equity Raised | B14: ='1. Assumptions'!B85+'1. Assumptions'!B86+'1. Assumptions'!B87 -> 0 | C14: ='1. Assumptions'!C85+'1. Assumptions'!C86+'1. Assumptions'!C87 -> 4 | D14: ='1. Assumptions'!D85+'1. Assumptions'!D86+'1. Assumptions'!D87 -> 13 | E14: ='1. Assumptions'!E85+'1. Assumptions'!E86+'1. Assumptions'!E87 -> 0 | F14: ='1. Assumptions'!F85+'1. Assumptions'!F86+'1. Assumptions'!F87 -> 40 | G14: ='1. Assumptions'!G85+'1. Assumptions'!G86+'1. Assumptions'!G87 -> 0 | H14: ='1. Assumptions'!H85+'1. Assumptions'!H86+'1. Assumptions'!H87 -> 0 | I14: ='1. Assumptions'!I85+'1. Assumptions'!I86+'1. Assumptions'!I87 -> 0 | ... L14: ='1. Assumptions'!L85+'1. Assumptions'!L86+'1. Assumptions'!L87 -> 0
A15: FINANCING CASH FLOW | B15: =B14 -> 0 | C15: =C14 -> 4 | D15: =D14 -> 13 | E15: =E14 -> 0 | F15: =F14 -> 40 | G15: =G14 -> 0 | H15: =H14 -> 0 | I15: =I14 -> 0 | ... L15: =L14 -> 0
A17: NET CASH FLOW | B17: =B7+B11+B15 -> 0 | C17: =C7+C11+C15 -> 5.11615 | D17: =D7+D11+D15 -> 16.09314 | E17: =E7+E11+E15 -> 7.520122 | F17: =F7+F11+F15 -> 58.7576 | G17: =G7+G11+G15 -> 35.454242 | H17: =H7+H11+H15 -> 41.94263 | I17: =I7+I11+I15 -> 52.275385 | ... L17: =L7+L11+L15 -> 70.583854
A18: CUMULATIVE CASH BALANCE | B18: =B17 -> 0 | C18: =B18+C17 -> 5.11615 | D18: =C18+D17 -> 21.20929 | E18: =D18+E17 -> 28.729412 | F18: =E18+F17 -> 87.487012 | G18: =F18+G17 -> 122.94125 | H18: =G18+H17 -> 164.88388 | I18: =H18+I17 -> 217.15927 | J18: =I18+J17 -> 273.92359 | ... L18: =K18+L17 -> 406.20164

Sheet 6. Cap Table
A1: CAP TABLE & DILUTION
A2: Shareholder | B2: Pre-Seed | C2: Post-Seed | D2: Post-Series A | E2: Post-Series B
A3: Founder | B3: 1 | C3: =1-B4-C5 -> 0.81818182 | D3: =C3*(1-D6/(D6+1)) -> 0.71783877 | E3: =D3*(1-E7/(E7+1)) -> 0.64831443
A4: ESOP | B4: 0 | C4: 0.1 | D4: 0.12 | E4: 0.15
A5: Seed Investors | B5: 0 | C5: =4/(18+4) -> 0.18181818 | D5: =C5*(1-D6/(D6+1)) -> 0.15951973 | E5: =D5*(1-E7/(E7+1)) -> 0.14406987
A6: Series A Investors | B6: 0 | C6: 0 | D6: =13/(80+13) -> 0.13978495 | E6: =D6*(1-E7/(E7+1)) -> 0.12624645
A7: Series B Investors | B7: 0 | C7: 0 | D7: 0 | E7: =40/(333+40) -> 0.10723861
A8: TOTAL | B8: =SUM(B3:B7) -> 1 | C8: =SUM(C3:C7) -> 1.1 | D8: =SUM(D3:D7) -> 1.1371434 | E8: =SUM(E3:E7) -> 1.1758694
A10: VALUATION SUMMARY
A11: Round | B11: Amount ($M) | C11: Pre-Money ($M) | D11: Post-Money ($M)
A12: Seed | B12: 4 | C12: 18 | D12: =B12+C12 -> 22
A13: Series A | B13: 13 | C13: 80 | D13: =B13+C13 -> 93
A14: Series B | B14: 40 | C14: 333 | D14: =B14+C14 -> 373

Sheet 7. Valuation
A1: EXIT SCENARIOS & INVESTOR RETURNS
A2: Scenario | B2: Revenue ($M) | C2: EV/Rev Multiple | D2: Exit Valuation ($M) | E2: Seed MOIC
A3: Scenario 1 — IPO (Tadawul, Year 7-8) | B3: 150 | C3: 17.5 | D3: =B3*C3 -> 2625 | E3: 8-12x
A4: Scenario 2 — Strategic Acquisition (Year 5-6) | B4: 80 | C4: 12.5 | D4: =B4*C4 -> 1000 | E4: 5-8x
A5: Scenario 3 — Sovereign Wealth (Year 4-5) | B5: 49 | C5: 10 | D5: =B5*C5 -> 490 | E5: 3-5x
A6: Scenario 4 — Independent Growth (Year 10) | B6: 300 | C6: 15 | D6: =B6*C6 -> 4500 | E6: 12-20x
A9: COMPARABLE COMPANY MULTIPLES
A10: Category | B10: Low | C10: High | D10: Median
A11: Infrastructure Companies (EV/Rev) | B11: 10 | C11: 20 | D11: =(B11+C11)/2 -> 15
A12: SaaS Companies (EV/Rev) | B12: 5 | C12: 8 | D12: =(B12+C12)/2 -> 6.5
A13: Healthcare Data (EV/Rev) | B13: 8 | C13: 15 | D13: =(B13+C13)/2 -> 11.5
A14: Clinical Trials CROs (EV/Rev) | B14: 3 | C14: 7 | D14: =(B14+C14)/2 -> 5

Sheet 8. Sensitivity
A1: SCENARIO ANALYSIS — YEAR 5
A2: Metric | B2: Bear Case | C2: Base Case | D2: Bull Case
A3: Revenue ($M) | B3: 39.8 | C3: 79.5 | D3: 119.3
A4: Gross Margin (%) | B4: 0.55 | C4: 0.7 | D4: 0.75
A5: Gross Profit ($M) | B5: =B3*B4 -> 21.89 | C5: =C3*C4 -> 55.65 | D5: =D3*D4 -> 89.475
A6: EBITDA ($M) | B6: =B5 -> 21.89 | C6: =C5 -> 55.65 | D6: =D5 -> 89.475
A7: Physician Adoption | B7: 12500 | C7: 25000 | D7: 37500
A8: Hospital Contracts | B8: 50 | C8: 100 | D8: 150
A9: Valuation ($M) @ 12.5x Rev | B9: =B3*12.5 -> 497.5 | C9: =C3*12.5 -> 993.75 | D9: =D3*12.5 -> 1491.25
A12: SENSITIVITY: HOSPITAL ACV IMPACT ON YEAR 5
A13: Hospital ACV ($K) | B13: Hospital Rev ($M) | C13: Total Rev Impact
A14: $75K | B14: 7.5 | C14: =B14+79.5-15 -> 72
A15: $100K | B15: 10 | C15: =B15+79.5-15 -> 74.5
A16: $125K | B16: 12.5 | C16: =B16+79.5-15 -> 77
A17: $150K | B17: 15 | C17: =B17+79.5-15 -> 79.5
A18: $175K | B18: 17.5 | C18: =B18+79.5-15 -> 82
A19: $200K | B19: 20 | C19: =B19+79.5-15 -> 84.5
A20: $250K | B20: 25 | C20: =B20+79.5-15 -> 89.5

Sheet 9. Intercompany
A1: INTERCOMPANY ECONOMICS (YEAR 5)
A2: Internal Transfer Pricing to SCII
A3: Entity | B3: Units | C3: $/Unit | D3: Annual ($K)
A4: NAMA Medical (active trials) | B4: 30 | C4: 50000 | D4: =B4*C4/1000 -> 1500
A5: NAMA Bio (studies) | B5: 20 | C5: 30000 | D5: =B5*C5/1000 -> 600
A6: WARAQA (indexing) | B6: 1 | C6: 20000 | D6: =B6*C6/1000 -> 20
A7: NAMA Knowledge (CME delivery) | B7: 1 | C7: 40000 | D7: =B7*C7/1000 -> 40
A8: TOTAL INTERNAL REVENUE TO SCII | D8: =SUM(D4:D7) -> 2160
A10: External vs. Internal Revenue (Year 5)
A11: Entity | B11: External ($M) | C11: Internal ($M) | D11: Total ($M) | E11: Internal %
A12: SCII Platform | B12: 25 | C12: 3.5 | D12: =B12+C12 -> 28.5 | E12: =IF(D12>0,C12/D12,0) -> 0.12280702
A13: NAMA Knowledge | B13: 12 | C13: 1 | D13: =B13+C13 -> 13 | E13: =IF(D13>0,C13/D13,0) -> 0.076923077
A14: NAMA Medical | B14: 18 | C14: 2.5 | D14: =B14+C14 -> 20.5 | E14: =IF(D14>0,C14/D14,0) -> 0.12195122
A15: NAMA Bio | B15: 11.5 | C15: 1.2 | D15: =B15+C15 -> 12.7 | E15: =IF(D15>0,C15/D15,0) -> 0.094488189
A16: WARAQA | B16: 4 | C16: 0.8 | D16: =B16+C16 -> 4.8 | E16: =IF(D16>0,C16/D16,0) -> 0.16666667
A17: TOTAL | B17: =SUM(B12:B16) -> 70.5 | C17: =SUM(C12:C16) -> 9 | D17: =SUM(D12:D16) -> 79.5 | E17: =IF(D17>0,C17/D17,0) -> 0.11320755
A19: Shared Services Savings (Year 5)
A20: Function | B20: Standalone ($K/entity) | C20: Shared ($K) | D20: Savings ($K/yr)
A21: Finance & Accounting | B21: 400 | C21: 600 | D21: 500
A22: HR & Recruiting | B22: 250 | C22: 400 | D22: 350
A23: Legal & Compliance | B23: 300 | C23: 700 | D23: 400
A24: IT Infrastructure | B24: 200 | C24: 1000 | D24: 1000
A25: TOTAL SAVINGS | D25: =SUM(D21:D24) -> 2250

Sheet 10. KPI Dashboard
A1: KEY PERFORMANCE INDICATORS
B2: Year 0 | C2: Year 1 | D2: Year 2 | E2: Year 3 | F2: Year 4 | G2: Year 5 | H2: Year 6 | I2: Year 7 | J2: Year 8 | K2: Year 9 | L2: Year 10
A3: Revenue ($M) | B3: ='2. Revenue'!B44 -> 0 | C3: ='2. Revenue'!C44 -> 5.845 | D3: ='2. Revenue'!D44 -> 10.581 | E3: ='2. Revenue'!E44 -> 24.2376 | F3: ='2. Revenue'!F44 -> 47.697 | G3: ='2. Revenue'!G44 -> 73.6448 | H3: ='2. Revenue'!H44 -> 88.867 | I3: ='2. Revenue'!I44 -> 109.7118 | ... L3: ='2. Revenue'!L44 -> 159.983
A4: Gross Margin (%) | B4: ='3. P&L'!B17 -> 0 | C4: ='3. P&L'!C17 -> 0.36204448 | D4: ='3. P&L'!D17 -> 0.45647292 | E4: ='3. P&L'!E17 -> 0.46221375 | F4: ='3. P&L'!F17 -> 0.50172065 | G4: ='3. P&L'!G17 -> 0.56693252 | H4: ='3. P&L'!H17 -> 0.57667582 | I4: ='3. P&L'!I17 -> 0.61040275 | ... L4: ='3. P&L'!L17 -> 0.63572298
A5: Net Income ($M) | B5: ='3. P&L'!B24 -> 0 | C5: ='3. P&L'!C24 -> 2.067052 | D5: ='3. P&L'!D24 -> 4.755873 | E5: ='3. P&L'!E24 -> 11.050255 | F5: ='3. P&L'!F24 -> 23.663467 | G5: ='3. P&L'!G24 -> 41.390772 | H5: ='3. P&L'!H24 -> 48.330498 | I5: ='3. P&L'!I24 -> 59.856835 | ... L5: ='3. P&L'!L24 -> 80.915944
A6: Cash Balance ($M) | B6: ='5. Cash Flow'!B18 -> 0 | C6: ='5. Cash Flow'!C18 -> 5.11615 | D6: ='5. Cash Flow'!D18 -> 21.20929 | E6: ='5. Cash Flow'!E18 -> 28.729412 | F6: ='5. Cash Flow'!F18 -> 87.487012 | G6: ='5. Cash Flow'!G18 -> 122.94125 | H6: ='5. Cash Flow'!H18 -> 164.88388 | I6: ='5. Cash Flow'!I18 -> 217.15927 | ... L6: ='5. Cash Flow'!L18 -> 406.20164
A7: Headcount (FTE) | B7: ='1. Assumptions'!B67 -> 0 | C7: ='1. Assumptions'!C67 -> 15 | D7: ='1. Assumptions'!D67 -> 25 | E7: ='1. Assumptions'!E67 -> 45 | F7: ='1. Assumptions'!F67 -> 60 | G7: ='1. Assumptions'!G67 -> 80 | H7: ='1. Assumptions'!H67 -> 95 | I7: ='1. Assumptions'!I67 -> 120 | ... L7: ='1. Assumptions'!L67 -> 180
A8: Rev/Employee ($K) | B8: =IF(B7>0,B3*1000/B7,0) -> 0 | C8: =IF(C7>0,C3*1000/C7,0) -> 389.66667 | D8: =IF(D7>0,D3*1000/D7,0) -> 423.24 | E8: =IF(E7>0,E3*1000/E7,0) -> 538.61333 | F8: =IF(F7>0,F3*1000/F7,0) -> 794.95 | G8: =IF(G7>0,G3*1000/G7,0) -> 920.56 | H8: =IF(H7>0,H3*1000/H7,0) -> 935.44211 | I8: =IF(I7>0,I3*1000/I7,0) -> 914.265 | ... L8: =IF(L7>0,L3*1000/L7,0) -> 888.79444
A9: Physicians | B9: ='1. Assumptions'!B13 -> 0 | C9: ='1. Assumptions'!C13 -> 2000 | D9: ='1. Assumptions'!D13 -> 5000 | E9: ='1. Assumptions'!E13 -> 15000 | F9: ='1. Assumptions'!F13 -> 35000 | G9: ='1. Assumptions'!G13 -> 80000 | H9: ='1. Assumptions'!H13 -> 100000 | I9: ='1. Assumptions'!I13 -> 120000 | ... L9: ='1. Assumptions'!L13 -> 200000
A10: SaaS | B10: ='2. Revenue'!B7 -> 0 | C10: ='2. Revenue'!C7 -> 0.45 | D10: ='2. Revenue'!D7 -> 2.109 | E10: ='2. Revenue'!E7 -> 8.4726 | F10: ='2. Revenue'!F7 -> 13.545 | G10: ='2. Revenue'!G7 -> 27.1248 | H10: ='2. Revenue'!H7 -> 30.96 | I10: ='2. Revenue'!I7 -> 39.0168 | ... L10: ='2. Revenue'!L7 -> 57.528
A11: CME | B11: ='2. Revenue'!B15 -> 0 | C11: ='2. Revenue'!C15 -> 5.395 | D11: ='2. Revenue'!D15 -> 7.602 | E11: ='2. Revenue'!E15 -> 9.405 | F11: ='2. Revenue'!F15 -> 10.122 | G11: ='2. Revenue'!G15 -> 10.72 | H11: ='2. Revenue'!H15 -> 12.287 | I11: ='2. Revenue'!I15 -> 13.755 | ... L11: ='2. Revenue'!L15 -> 18.555
A12: Trials | B12: ='2. Revenue'!B22 -> 0 | C12: ='2. Revenue'!C22 -> 0 | D12: ='2. Revenue'!D22 -> 0 | E12: ='2. Revenue'!E22 -> 4.3 | F12: ='2. Revenue'!F22 -> 9.45 | G12: ='2. Revenue'!G22 -> 12.4 | H12: ='2. Revenue'!H22 -> 17.1 | I12: ='2. Revenue'!I22 -> 21.3 | ... L12: ='2. Revenue'!L22 -> 30.9
A13: Publishing | B13: ='2. Revenue'!B29 -> 0 | C13: ='2. Revenue'!C29 -> 0 | D13: ='2. Revenue'!D29 -> 0.87 | E13: ='2. Revenue'!E29 -> 2.06 | F13: ='2. Revenue'!F29 -> 2.63 | G13: ='2. Revenue'!G29 -> 3 | H13: ='2. Revenue'!H29 -> 3.57 | I13: ='2. Revenue'!I29 -> 4.14 | ... L13: ='2. Revenue'!L29 -> 5.85
A14: Bioequivalence | B14: ='2. Revenue'!B35 -> 0 | C14: ='2. Revenue'!C35 -> 0 | D14: ='2. Revenue'!D35 -> 0 | E14: ='2. Revenue'!E35 -> 0 | F14: ='2. Revenue'!F35 -> 6.9 | G14: ='2. Revenue'!G35 -> 11.4 | H14: ='2. Revenue'!H35 -> 14 | I14: ='2. Revenue'!I35 -> 16.6 | ... L14: ='2. Revenue'!L35 -> 24.4
A15: Data Licensing | B15: ='2. Revenue'!B41 -> 0 | C15: ='2. Revenue'!C41 -> 0 | D15: ='2. Revenue'!D41 -> 0 | E15: ='2. Revenue'!E41 -> 0 | F15: ='2. Revenue'!F41 -> 5.05 | G15: ='2. Revenue'!G41 -> 9 | H15: ='2. Revenue'!H41 -> 10.95 | I15: ='2. Revenue'!I41 -> 14.9 | ... L15: ='2. Revenue'!L41 -> 22.75

Sheet 11. Use of Proceeds
A1: USE OF PROCEEDS BY ROUND
A2: SEED ROUND — $4M (SAR 15M)
A3: Category | B3: % Allocation | C3: Amount ($M) | D3: Description
A4: Technology MVP | B4: 0.4 | C4: =B4*4 -> 1.6 | D4: Evidence engine, KG v1, CME integration
A5: Core Team Hiring | B5: 0.3 | C5: =B5*4 -> 1.2 | D5: CTO, VP Eng, 6 engineers, Medical Dir
A6: Institute Integration | B6: 0.15 | C6: =B6*4 -> 0.6 | D6: Infra, onboarding systems
A7: Ops & Legal | B7: 0.15 | C7: =B7*4 -> 0.6 | D7: Office, licensing, compliance
A8: TOTAL | B8: =SUM(B4:B7) -> 1 | C8: =SUM(C4:C7) -> 4
A10: SERIES A — $13M (SAR 50M)
A11: Category | B11: % Allocation | C11: Amount ($M) | D11: Description
A12: Product Expansion | B12: 0.35 | C12: =B12*13 -> 4.55 | D12: CTMS, RWD platform, Arabic AI v1
A13: Clinical Trials Infra | B13: 0.25 | C13: =B13*13 -> 3.25 | D13: NAMA Medical setup, site network
A14: Publishing Platform | B14: 0.2 | C14: =B14*13 -> 2.6 | D14: WARAQA journal, review tools
A15: Market Expansion | B15: 0.15 | C15: =B15*13 -> 1.95 | D15: Enterprise sales, pharma BD
A16: Operations | B16: 0.05 | C16: =B16*13 -> 0.65 | D16: Scaling shared services
A17: TOTAL | B17: =SUM(B12:B16) -> 1 | C17: =SUM(C12:C16) -> 13
A19: SERIES B — $40M (SAR 150M)
A20: Category | B20: % Allocation | C20: Amount ($M) | D20: Description
A21: GCC Expansion | B21: 0.3 | C21: =B21*40 -> 12 | D21: UAE, Kuwait offices, regulatory, local teams
A22: NAMA Bio Center | B22: 0.25 | C22: =B22*40 -> 10 | D22: Lab, equipment, SFDA certification
A23: Technology at Scale | B23: 0.2 | C23: =B23*40 -> 8 | D23: Sovereign cloud, AI training, KG expansion
A24: Government Contracts | B24: 0.15 | C24: =B24*40 -> 6 | D24: MOH, SCFHS, SFDA implementations
A25: Strategic Reserve | B25: 0.1 | C25: =B25*40 -> 4 | D25: M&A, contingency
A26: TOTAL | B26: =SUM(B21:B25) -> 1 | C26: =SUM(C21:C25) -> 40
