Workbook

Sheet Consolidated TKG
A1: TKG - THEEB KNOWLEDGE GROUP | CONSOLIDATED P&L
A2: SAR Thousands | Conservative Scenario | 2026-2030
B3: 2026 | C3: 2027 | D3: 2028 | E3: 2029 | F3: 2030
A4: REVENUE BY ENTITY
A5: Waraqa (TKG-01) | B5: ='Waraqa (TKG-01)'!B14 | C5: ='Waraqa (TKG-01)'!C14 | D5: ='Waraqa (TKG-01)'!D14 | E5: ='Waraqa (TKG-01)'!E14 | F5: ='Waraqa (TKG-01)'!F14
A6: Nama CRO (TKG-02) | B6: ='Nama CRO (TKG-02)'!B11 | C6: ='Nama CRO (TKG-02)'!C11 | D6: ='Nama CRO (TKG-02)'!D11 | E6: ='Nama CRO (TKG-02)'!E11 | F6: ='Nama CRO (TKG-02)'!F11
A7: Nama Academy (TKG-03) | B7: ='Nama Academy (TKG-03)'!B11 | C7: ='Nama Academy (TKG-03)'!C11 | D7: ='Nama Academy (TKG-03)'!D11 | E7: ='Nama Academy (TKG-03)'!E11 | F7: ='Nama Academy (TKG-03)'!F11
A8: Nama Bio (TKG-04) | B8: ='Nama Bio (TKG-04)'!B6 | C8: ='Nama Bio (TKG-04)'!C6 | D8: ='Nama Bio (TKG-04)'!D6 | E8: ='Nama Bio (TKG-04)'!E6 | F8: ='Nama Bio (TKG-04)'!F6
A9: Saudi Evidence (TKG-05) | B9: ='Saudi Evidence (TKG-05)'!B9 | C9: ='Saudi Evidence (TKG-05)'!C9 | D9: ='Saudi Evidence (TKG-05)'!D9 | E9: ='Saudi Evidence (TKG-05)'!E9 | F9: ='Saudi Evidence (TKG-05)'!F9
A10: TOTAL GROSS REVENUE | B10: =SUM(B5:B9) | C10: =SUM(C5:C9) | D10: =SUM(D5:D9) | E10: =SUM(E5:E9) | F10: =SUM(F5:F9)
A11: Inter-company Eliminations | B11: -700 | C11: -1500 | D11: -2500 | E11: -3500 | F11: -4500
A12: TOTAL NET REVENUE | B12: =B10+B11 | C12: =C10+C11 | D12: =D10+D11 | E12: =E10+E11 | F12: =F10+F11
A13: Revenue Growth % | B13: N/A | C13: =IF(B12=0,0,(C12-B12)/B12) | D13: =IF(C12=0,0,(D12-C12)/C12) | E13: =IF(D12=0,0,(E12-D12)/D12) | F13: =IF(E12=0,0,(F12-E12)/E12)
A15: TOTAL COSTS BY ENTITY
A16: Waraqa Total Costs | B16: ='Waraqa (TKG-01)'!B23+'Waraqa (TKG-01)'!B34+'Waraqa (TKG-01)'!B41 | C16: ='Waraqa (TKG-01)'!C23+'Waraqa (TKG-01)'!C34+'Waraqa (TKG-01)'!C41 | D16: ='Waraqa (TKG-01)'!D23+'Waraqa (TKG-01)'!D34+'Waraqa (TKG-01)'!D41 | E16: ='Waraqa (TKG-01)'!E23+'Waraqa (TKG-01)'!E34+'Waraqa (TKG-01)'!E41 | F16: ='Waraqa (TKG-01)'!F23+'Waraqa (TKG-01)'!F34+'Waraqa (TKG-01)'!F41
A17: Nama CRO Total Costs | B17: ='Nama CRO (TKG-02)'!B21+'Nama CRO (TKG-02)'!B32+'Nama CRO (TKG-02)'!B39 | C17: ='Nama CRO (TKG-02)'!C21+'Nama CRO (TKG-02)'!C32+'Nama CRO (TKG-02)'!C39 | D17: ='Nama CRO (TKG-02)'!D21+'Nama CRO (TKG-02)'!D32+'Nama CRO (TKG-02)'!D39 | E17: ='Nama CRO (TKG-02)'!E21+'Nama CRO (TKG-02)'!E32+'Nama CRO (TKG-02)'!E39 | F17: ='Nama CRO (TKG-02)'!F21+'Nama CRO (TKG-02)'!F32+'Nama CRO (TKG-02)'!F39
A18: Nama Academy Total Costs | B18: ='Nama Academy (TKG-03)'!B23+'Nama Academy (TKG-03)'!B33+'Nama Academy (TKG-03)'!B40 | C18: ='Nama Academy (TKG-03)'!C23+'Nama Academy (TKG-03)'!C33+'Nama Academy (TKG-03)'!C40 | D18: ='Nama Academy (TKG-03)'!D23+'Nama Academy (TKG-03)'!D33+'Nama Academy (TKG-03)'!D40 | E18: ='Nama Academy (TKG-03)'!E23+'Nama Academy (TKG-03)'!E33+'Nama Academy (TKG-03)'!E40 | F18: ='Nama Academy (TKG-03)'!F23+'Nama Academy (TKG-03)'!F33+'Nama Academy (TKG-03)'!F40
A19: Nama Bio Total Costs | B19: ='Nama Bio (TKG-04)'!B15+'Nama Bio (TKG-04)'!B28+'Nama Bio (TKG-04)'!B35 | C19: ='Nama Bio (TKG-04)'!C15+'Nama Bio (TKG-04)'!C28+'Nama Bio (TKG-04)'!C35 | D19: ='Nama Bio (TKG-04)'!D15+'Nama Bio (TKG-04)'!D28+'Nama Bio (TKG-04)'!D35 | E19: ='Nama Bio (TKG-04)'!E15+'Nama Bio (TKG-04)'!E28+'Nama Bio (TKG-04)'!E35 | F19: ='Nama Bio (TKG-04)'!F15+'Nama Bio (TKG-04)'!F28+'Nama Bio (TKG-04)'!F35
A20: Saudi Evidence Total Costs | B20: ='Saudi Evidence (TKG-05)'!B18+'Saudi Evidence (TKG-05)'!B28+'Saudi Evidence (TKG-05)'!B35 | C20: ='Saudi Evidence (TKG-05)'!C18+'Saudi Evidence (TKG-05)'!C28+'Saudi Evidence (TKG-05)'!C35 | D20: ='Saudi Evidence (TKG-05)'!D18+'Saudi Evidence (TKG-05)'!D28+'Saudi Evidence (TKG-05)'!D35 | E20: ='Saudi Evidence (TKG-05)'!E18+'Saudi Evidence (TKG-05)'!E28+'Saudi Evidence (TKG-05)'!E35 | F20: ='Saudi Evidence (TKG-05)'!F18+'Saudi Evidence (TKG-05)'!F28+'Saudi Evidence (TKG-05)'!F35
A21: TOTAL COSTS | B21: =SUM(B16:B20) | C21: =SUM(C16:C20) | D21: =SUM(D16:D20) | E21: =SUM(E16:E20) | F21: =SUM(F16:F20)
A23: EBITDA BY ENTITY
A24: Waraqa EBITDA | B24: ='Waraqa (TKG-01)'!B45 | C24: ='Waraqa (TKG-01)'!C45 | D24: ='Waraqa (TKG-01)'!D45 | E24: ='Waraqa (TKG-01)'!E45 | F24: ='Waraqa (TKG-01)'!F45
A25: Nama CRO EBITDA | B25: ='Nama CRO (TKG-02)'!B43 | C25: ='Nama CRO (TKG-02)'!C43 | D25: ='Nama CRO (TKG-02)'!D43 | E25: ='Nama CRO (TKG-02)'!E43 | F25: ='Nama CRO (TKG-02)'!F43
A26: Nama Academy EBITDA | B26: ='Nama Academy (TKG-03)'!B44 | C26: ='Nama Academy (TKG-03)'!C44 | D26: ='Nama Academy (TKG-03)'!D44 | E26: ='Nama Academy (TKG-03)'!E44 | F26: ='Nama Academy (TKG-03)'!F44
A27: Nama Bio EBITDA | B27: ='Nama Bio (TKG-04)'!B39 | C27: ='Nama Bio (TKG-04)'!C39 | D27: ='Nama Bio (TKG-04)'!D39 | E27: ='Nama Bio (TKG-04)'!E39 | F27: ='Nama Bio (TKG-04)'!F39
A28: Saudi Evidence EBITDA | B28: ='Saudi Evidence (TKG-05)'!B39 | C28: ='Saudi Evidence (TKG-05)'!C39 | D28: ='Saudi Evidence (TKG-05)'!D39 | E28: ='Saudi Evidence (TKG-05)'!E39 | F28: ='Saudi Evidence (TKG-05)'!F39
A29: Holding Allocation (shared services) | B29: -500 | C29: -600 | D29: -700 | E29: -800 | F29: -900
A30: TOTAL TKG EBITDA | B30: =SUM(B24:B29) | C30: =SUM(C24:C29) | D30: =SUM(D24:D29) | E30: =SUM(E24:E29) | F30: =SUM(F24:F29)
A31: TKG EBITDA Margin % | B31: =IF(B12=0,0,B30/B12) | C31: =IF(C12=0,0,C30/C12) | D31: =IF(D12=0,0,D30/D12) | E31: =IF(E12=0,0,E30/E12) | F31: =IF(F12=0,0,F30/F12)
A32: EBITDA Growth % | B32: N/A | C32: =IF(B30=0,0,(C30-B30)/B30) | D32: =IF(C30=0,0,(D30-C30)/C30) | E32: =IF(D30=0,0,(E30-D30)/D30) | F32: =IF(E30=0,0,(F30-E30)/E30)
A34: HEADCOUNT BY ENTITY
A35: Waraqa | B35: ='Waraqa (TKG-01)'!B52 | C35: ='Waraqa (TKG-01)'!C52 | D35: ='Waraqa (TKG-01)'!D52 | E35: ='Waraqa (TKG-01)'!E52 | F35: ='Waraqa (TKG-01)'!F52
A36: Nama CRO | B36: ='Nama CRO (TKG-02)'!B47 | C36: ='Nama CRO (TKG-02)'!C47 | D36: ='Nama CRO (TKG-02)'!D47 | E36: ='Nama CRO (TKG-02)'!E47 | F36: ='Nama CRO (TKG-02)'!F47
A37: Nama Academy | B37: ='Nama Academy (TKG-03)'!B48 | C37: ='Nama Academy (TKG-03)'!C48 | D37: ='Nama Academy (TKG-03)'!D48 | E37: ='Nama Academy (TKG-03)'!E48 | F37: ='Nama Academy (TKG-03)'!F48
A38: Nama Bio | B38: ='Nama Bio (TKG-04)'!B49 | C38: ='Nama Bio (TKG-04)'!C49 | D38: ='Nama Bio (TKG-04)'!D49 | E38: ='Nama Bio (TKG-04)'!E49 | F38: ='Nama Bio (TKG-04)'!F49
A39: Saudi Evidence | B39: ='Saudi Evidence (TKG-05)'!B43 | C39: ='Saudi Evidence (TKG-05)'!C43 | D39: ='Saudi Evidence (TKG-05)'!D43 | E39: ='Saudi Evidence (TKG-05)'!E43 | F39: ='Saudi Evidence (TKG-05)'!F43
A40: TOTAL TKG HEADCOUNT | B40: =SUM(B35:B39) | C40: =SUM(C35:C39) | D40: =SUM(D35:D39) | E40: =SUM(E35:E39) | F40: =SUM(F35:F39)
A42: CAPITAL DEPLOYMENT (SAR '000)
A43: Nama CRO (Alfaisaliah Equity) | B43: 9375 | C43: 7500 | D43: 1875 | E43: 0 | F43: 0
A44: Nama Bio (Govt Grant + Equity) | B44: 8206 | C44: 1400 | D44: 1150 | E44: 0 | F44: 0
...

Sheet Waraqa (TKG-01)
A1: WARAQA PUBLISHING HOUSE (TKG-01)
A2: P&L Statement | SAR Thousands | Conservative
B3: 2026 | C3: 2027 | D3: 2028 | E3: 2029 | F3: 2030
A4: REVENUE
A5: 1. Society Journal Publishing | B5: 234 | C5: 860 | D5: 3600 | E5: 5400 | F5: 7200
A6: 2. University Preprint Platform | B6: 24 | C6: 200 | D6: 1500 | E6: 2500 | F6: 3500
A7: 3. Funded Journal Operations | B7: 360 | C7: 480 | D7: 650 | E7: 700 | F7: 750
A8: 4. Research Integrity Services | B8: 360 | C8: 800 | D8: 1800 | E8: 2700 | F8: 3500
A9: 5. Conference Proceedings | B9: 240 | C9: 500 | D9: 1200 | E9: 1800 | F9: 2400
A10: 6. Ecosystem Cross-Group | B10: 100 | C10: 300 | D10: 700 | E10: 1000 | F10: 1500
A11: 7. AI Content Licensing | B11: 0 | C11: 500 | D11: 2000 | E11: 4000 | F11: 7000
A12: 8. PubHelper Services | B12: 400 | C12: 800 | D12: 1500 | E12: 2500 | F12: 3500
A13: 9. Physician Reputation Platform | B13: 200 | C13: 1200 | D13: 3000 | E13: 5000 | F13: 7000
A14: TOTAL REVENUE | B14: =SUM(B5:B13) | C14: =SUM(C5:C13) | D14: =SUM(D5:D13) | E14: =SUM(E5:E13) | F14: =SUM(F5:F13)
A15: Revenue Growth % | B15: N/A | C15: =IF(B14=0,0,(C14-B14)/B14) | D15: =IF(C14=0,0,(D14-C14)/C14) | E15: =IF(D14=0,0,(E14-D14)/D14) | F15: =IF(E14=0,0,(F14-E14)/E14)
A17: DIRECT COSTS (COGS)
A18: Editorial & Content Production | B18: 350 | C18: 600 | D18: 1400 | E18: 2200 | F18: 3000
A19: Platform & Technology | B19: 150 | C19: 300 | D19: 600 | E19: 900 | F19: 1200
A20: Freelance Writers & Editors | B20: 150 | C20: 300 | D20: 800 | E20: 1200 | F20: 1800
A21: Journal Operations & Indexing | B21: 100 | C21: 200 | D21: 400 | E21: 600 | F21: 800
A22: AI Content Preparation | B22: 0 | C22: 100 | D22: 300 | E22: 600 | F22: 700
A23: TOTAL COGS | B23: =SUM(B18:B22) | C23: =SUM(C18:C22) | D23: =SUM(D18:D22) | E23: =SUM(E18:E22) | F23: =SUM(F18:F22)
A24: GROSS PROFIT | B24: =B14-B23 | C24: =C14-C23 | D24: =D14-D23 | E24: =E14-E23 | F24: =F14-F23
A25: Gross Margin % | B25: =IF(B14=0,0,B24/B14) | C25: =IF(C14=0,0,C24/C14) | D25: =IF(D14=0,0,D24/D14) | E25: =IF(E14=0,0,E24/E14) | F25: =IF(F14=0,0,F24/F14)
A27: GENERAL & ADMINISTRATIVE
A28: Staff Salaries (editorial + ops) | B28: 350 | C28: 500 | D28: 750 | E28: 950 | F28: 1200
A29: Rent & Office | B29: 80 | C29: 100 | D29: 150 | E29: 200 | F29: 250
A30: IT Infrastructure | B30: 50 | C30: 80 | D30: 120 | E30: 150 | F30: 180
A31: Legal & Compliance | B31: 40 | C31: 50 | D31: 70 | E31: 80 | F31: 100
A32: International Advisory | B32: 80 | C32: 70 | D32: 60 | E32: 50 | F32: 50
A33: Hiring & Training | B33: 30 | C33: 40 | D33: 50 | E33: 60 | F33: 70
A34: TOTAL G&A | B34: =SUM(B28:B33) | C34: =SUM(C28:C33) | D34: =SUM(D28:D33) | E34: =SUM(E28:E33) | F34: =SUM(F28:F33)
A36: SALES & MARKETING
A37: Sales & Marketing Staff | B37: 80 | C37: 120 | D37: 200 | E37: 300 | F37: 400
A38: Business Development | B38: 60 | C38: 100 | D38: 150 | E38: 200 | F38: 250
A39: Events & Partnerships | B39: 40 | C39: 80 | D39: 100 | E39: 130 | F39: 170
A40: Digital Marketing | B40: 20 | C40: 50 | D40: 50 | E40: 70 | F40: 80
A41: TOTAL S&M | B41: =SUM(B37:B40) | C41: =SUM(C37:C40) | D41: =SUM(D37:D40) | E41: =SUM(E37:E40) | F41: =SUM(F37:F40)
A43: TOTAL OPERATING EXPENSES | B43: =B34+B41 | C43: =C34+C41 | D43: =D34+D41 | E43: =E34+E41 | F43: =F34+F41
A45: EBITDA | B45: =B24-B43 | C45: =C24-C43 | D45: =D24-D43 | E45: =E24-E43 | F45: =F24-F43
...

Sheet Nama CRO (TKG-02)
A1: NAMA CRO / NAMA MEDICAL (TKG-02)
A2: P&L Statement | SAR Thousands | Conservative
B3: 2026 | C3: 2027 | D3: 2028 | E3: 2029 | F3: 2030
A4: REVENUE
A5: 1. Interventional Trials (Phase I-IV) | B5: 1500 | C5: 4500 | D5: 9000 | E5: 15000 | F5: 22500
A6: 2. RWE & Observational Studies | B6: 750 | C6: 2250 | D6: 4500 | E6: 7500 | F6: 11250
A7: 3. CTU Development Contracts | B7: 500 | C7: 1200 | D7: 2000 | E7: 3000 | F7: 4000
A8: 4. SMO Services | B8: 375 | C8: 750 | D8: 1500 | E8: 2250 | F8: 3000
A9: 5. Training & Capability Building | B9: 200 | C9: 500 | D9: 1000 | E9: 1500 | F9: 2000
A10: 6. Medical Writing (to Waraqa SLA) | B10: 300 | C10: 450 | D10: 600 | E10: 750 | F10: 900
A11: TOTAL REVENUE | B11: =SUM(B5:B10) | C11: =SUM(C5:C10) | D11: =SUM(D5:D10) | E11: =SUM(E5:E10) | F11: =SUM(F5:F10)
A12: Revenue Growth % | B12: N/A | C12: =IF(B11=0,0,(C11-B11)/B11) | D12: =IF(C11=0,0,(D11-C11)/C11) | E12: =IF(D11=0,0,(E11-D11)/D11) | F12: =IF(E11=0,0,(F11-E11)/E11)
A14: DIRECT COSTS (COGS)
A15: Clinical Research Associates | B15: 600 | C15: 1500 | D15: 3000 | E15: 5000 | F15: 7500
A16: Study Coordinators & Site Staff | B16: 400 | C16: 1000 | D16: 2000 | E16: 3000 | F16: 4500
A17: Principal Investigators (PTC) | B17: 500 | C17: 1500 | D17: 3000 | E17: 4500 | F17: 6000
A18: Data Management & Biostatistics | B18: 300 | C18: 700 | D18: 1200 | E18: 1800 | F18: 2000
A19: Regulatory & Pharmacovigilance | B19: 200 | C19: 400 | D19: 700 | E19: 1000 | F19: 1200
A20: Laboratory & Logistics | B20: 200 | C20: 400 | D20: 600 | E20: 700 | F20: 800
A21: TOTAL COGS | B21: =SUM(B15:B20) | C21: =SUM(C15:C20) | D21: =SUM(D15:D20) | E21: =SUM(E15:E20) | F21: =SUM(F15:F20)
A22: GROSS PROFIT | B22: =B11-B21 | C22: =C11-C21 | D22: =D11-D21 | E22: =E11-E21 | F22: =F11-F21
A23: Gross Margin % | B23: =IF(B11=0,0,B22/B11) | C23: =IF(C11=0,0,C22/C11) | D23: =IF(D11=0,0,D22/D11) | E23: =IF(E11=0,0,E22/E11) | F23: =IF(F11=0,0,F22/F11)
A25: GENERAL & ADMINISTRATIVE
A26: Management & Admin Salaries | B26: 600 | C26: 700 | D26: 900 | E26: 1100 | F26: 1300
A27: Office Rent (KSA + Egypt + UAE) | B27: 250 | C27: 300 | D27: 400 | E27: 500 | F27: 600
A28: IT Systems (CTMS, LMS, EDC) | B28: 200 | C28: 250 | D28: 350 | E28: 450 | F28: 550
A29: Legal & Regulatory Compliance | B29: 80 | C29: 100 | D29: 150 | E29: 200 | F29: 250
A30: Insurance & Professional Fees | B30: 40 | C30: 80 | D30: 120 | E30: 150 | F30: 180
A31: Hiring & Onboarding | B31: 30 | C31: 70 | D31: 80 | E31: 100 | F31: 120
A32: TOTAL G&A | B32: =SUM(B26:B31) | C32: =SUM(C26:C31) | D32: =SUM(D26:D31) | E32: =SUM(E26:E31) | F32: =SUM(F26:F31)
A34: SALES & MARKETING
A35: Business Development | B35: 120 | C35: 200 | D35: 350 | E35: 450 | F35: 550
A36: Marketing & Brand | B36: 100 | C36: 150 | D36: 250 | E36: 300 | F36: 350
A37: Travel (client meetings, sites) | B37: 50 | C37: 100 | D37: 150 | E37: 200 | F37: 250
A38: Conference Participation | B38: 30 | C38: 50 | D38: 50 | E38: 50 | F38: 50
A39: TOTAL S&M | B39: =SUM(B35:B38) | C39: =SUM(C35:C38) | D39: =SUM(D35:D38) | E39: =SUM(E35:E38) | F39: =SUM(F35:F38)
A41: TOTAL OPERATING EXPENSES | B41: =B32+B39 | C41: =C32+C39 | D41: =D32+D39 | E41: =E32+E39 | F41: =F32+F39
A43: EBITDA | B43: =B22-B41 | C43: =C22-C41 | D43: =D22-D41 | E43: =E22-E41 | F43: =F22-F41
A44: EBITDA Margin % | B44: =IF(B11=0,0,B43/B11) | C44: =IF(C11=0,0,C43/C11) | D44: =IF(D11=0,0,D43/D11) | E44: =IF(E11=0,0,E43/E11) | F44: =IF(F11=0,0,F43/F11)
A46: OPERATIONAL METRICS
...

Sheet Nama Academy (TKG-03)
A1: NAMA ACADEMY (TKG-03)
A2: P&L Statement | SAR Thousands | Conservative
B3: 2026 | C3: 2027 | D3: 2028 | E3: 2029 | F3: 2030
A4: REVENUE
A5: 1. SHA Life Support (BLS/ACLS/PALS/NRP) | B5: 800 | C5: 1800 | D5: 3500 | E5: 5500 | F5: 8000
A6: 2. Specialty CME Programs | B6: 400 | C6: 1000 | D6: 2500 | E6: 4000 | F6: 6000
A7: 3. Academy-as-a-Service (AaaS) | B7: 0 | C7: 500 | D7: 1500 | E7: 3000 | F7: 5000
A8: 4. Conference & Society CME | B8: 300 | C8: 800 | D8: 1500 | E8: 2500 | F8: 3500
A9: 5. MGA Bundle CME Revenue Share | B9: 0 | C9: 200 | D9: 600 | E9: 1200 | F9: 2000
A10: 6. HRDF/Tamheer Programs | B10: 200 | C10: 400 | D10: 700 | E10: 1000 | F10: 1500
A11: TOTAL REVENUE | B11: =SUM(B5:B10) | C11: =SUM(C5:C10) | D11: =SUM(D5:D10) | E11: =SUM(E5:E10) | F11: =SUM(F5:F10)
A12: Revenue Growth % | B12: N/A | C12: =IF(B11=0,0,(C11-B11)/B11) | D12: =IF(C11=0,0,(D11-C11)/C11) | E12: =IF(D11=0,0,(E11-D11)/D11) | F12: =IF(E11=0,0,(F11-E11)/E11)
A14: DIRECT COSTS (COGS)
A15: Trainers & Instructors | B15: 400 | C15: 900 | D15: 1800 | E15: 2800 | F15: 4200
A16: Venue & Simulation Center Rental | B16: 250 | C16: 500 | D16: 1000 | E16: 1600 | F16: 2400
A17: Training Materials & Equipment | B17: 150 | C17: 350 | D17: 700 | E17: 1100 | F17: 1600
A18: CME Accreditation Fees (SCFHS) | B18: 50 | C18: 100 | D18: 200 | E18: 300 | F18: 400
A19: Conference Production Costs | B19: 100 | C19: 300 | D19: 600 | E19: 1000 | F19: 1400
A20: AaaS Operations (dedicated staff) | B20: 0 | C20: 200 | D20: 500 | E20: 900 | F20: 1500
A21: MGA Bundle Administration | B21: 0 | C21: 50 | D21: 100 | E21: 200 | F21: 300
A22: HRDF Program Delivery | B22: 150 | C22: 100 | D22: 100 | E22: 100 | F22: 200
A23: TOTAL COGS | B23: =SUM(B15:B22) | C23: =SUM(C15:C22) | D23: =SUM(D15:D22) | E23: =SUM(E15:E22) | F23: =SUM(F15:F22)
A24: GROSS PROFIT | B24: =B11-B23 | C24: =C11-C23 | D24: =D11-D23 | E24: =E11-E23 | F24: =F11-F23
A25: Gross Margin % | B25: =IF(B11=0,0,B24/B11) | C25: =IF(C11=0,0,C24/C11) | D25: =IF(D11=0,0,D24/D11) | E25: =IF(E11=0,0,E24/E11) | F25: =IF(F11=0,0,F24/F11)
A27: GENERAL & ADMINISTRATIVE
A28: Management & Admin Salaries | B28: 300 | C28: 400 | D28: 550 | E28: 700 | F28: 850
A29: Office & Admin | B29: 80 | C29: 100 | D29: 150 | E29: 200 | F29: 250
A30: IT & LMS Platform | B30: 60 | C30: 100 | D30: 150 | E30: 200 | F30: 250
A31: Legal & SCFHS Compliance | B31: 30 | C31: 50 | D31: 80 | E31: 100 | F31: 120
A32: Hiring & Staff Development | B32: 30 | C32: 50 | D32: 70 | E32: 100 | F32: 130
A33: TOTAL G&A | B33: =SUM(B28:B32) | C33: =SUM(C28:C32) | D33: =SUM(D28:D32) | E33: =SUM(E28:E32) | F33: =SUM(F28:F32)
A35: SALES & MARKETING
A36: Marketing & Outreach | B36: 60 | C36: 120 | D36: 200 | E36: 300 | F36: 400
A37: Business Development (AaaS) | B37: 50 | C37: 100 | D37: 180 | E37: 250 | F37: 320
A38: Digital & Content Marketing | B38: 20 | C38: 50 | D38: 80 | E38: 100 | F38: 120
A39: Travel & Events | B39: 20 | C39: 30 | D39: 40 | E39: 50 | F39: 60
A40: TOTAL S&M | B40: =SUM(B36:B39) | C40: =SUM(C36:C39) | D40: =SUM(D36:D39) | E40: =SUM(E36:E39) | F40: =SUM(F36:F39)
A42: TOTAL OPERATING EXPENSES | B42: =B33+B40 | C42: =C33+C40 | D42: =D33+D40 | E42: =E33+E40 | F42: =F33+F40
A44: EBITDA | B44: =B24-B42 | C44: =C24-C42 | D44: =D24-D42 | E44: =E24-E42 | F44: =F24-F42
A45: EBITDA Margin % | B45: =IF(B11=0,0,B44/B11) | C45: =IF(C11=0,0,C44/C11) | D45: =IF(D11=0,0,D44/D11) | E45: =IF(E11=0,0,E44/E11) | F45: =IF(F11=0,0,F44/F11)
...

Sheet Nama Bio (TKG-04)
A1: NAMA BIOEQUIVALENCE CENTER (TKG-04)
A2: P&L Statement | SAR Thousands | Conservative
B3: 2026 | C3: 2027 | D3: 2028 | E3: 2029 | F3: 2030
A4: REVENUE
A5: 1. Bioequivalence Studies | B5: 2700 | C5: 4500 | D5: 8100 | E5: 10238 | F5: 13650
A6: TOTAL REVENUE | B6: =SUM(B5:B5) | C6: =SUM(C5:C5) | D6: =SUM(D5:D5) | E6: =SUM(E5:E5) | F6: =SUM(F5:F5)
A7: Revenue Growth % | B7: N/A | C7: =IF(B6=0,0,(C6-B6)/B6) | D7: =IF(C6=0,0,(D6-C6)/C6) | E7: =IF(D6=0,0,(E6-D6)/D6) | F7: =IF(E6=0,0,(F6-E6)/E6)
A9: DIRECT COSTS (COGS)
A10: Principal Trial Costs (PTC) | B10: 960 | C10: 2800 | D10: 5520 | E10: 6640 | F10: 8560
A11: Direct Clinical Labor | B11: 550 | C11: 1100 | D11: 2000 | E11: 2800 | F11: 3600
A12: Laboratory & Bioanalytical (KSU) | B12: 250 | C12: 400 | D12: 500 | E12: 700 | F12: 1000
A13: Maintenance & Consumables | B13: 62 | C13: 79 | D13: 100 | E13: 138 | F13: 173
A14: Transportation & Logistics | B14: 50 | C14: 100 | D14: 100 | E14: 100 | F14: 100
A15: TOTAL COGS | B15: =SUM(B10:B14) | C15: =SUM(C10:C14) | D15: =SUM(D10:D14) | E15: =SUM(E10:E14) | F15: =SUM(F10:F14)
A16: GROSS PROFIT | B16: =B6-B15 | C16: =C6-C15 | D16: =D6-D15 | E16: =E6-E15 | F16: =F6-F15
A17: Gross Margin % | B17: =IF(B6=0,0,B16/B6) | C17: =IF(C6=0,0,C16/C6) | D17: =IF(D6=0,0,D16/D6) | E17: =IF(E6=0,0,E16/E6) | F17: =IF(F6=0,0,F16/F6)
A19: GENERAL & ADMINISTRATIVE
A20: Management Salaries | B20: 800 | C20: 850 | D20: 1200 | E20: 1300 | F20: 1400
A21: Admin & Support Staff | B21: 450 | C21: 500 | D21: 700 | E21: 750 | F21: 800
A22: Rent (CARE Medical Ward) | B22: 250 | C22: 263 | D22: 275 | E22: 289 | F22: 304
A23: Utilities & Telecom | B23: 60 | C23: 63 | D23: 66 | E23: 69 | F23: 73
A24: IT & Systems | B24: 150 | C24: 158 | D24: 165 | E24: 174 | F24: 182
A25: Regulatory & QA | B25: 200 | C25: 180 | D25: 350 | E25: 400 | F25: 400
A26: Hiring Costs | B26: 60 | C26: 62 | D26: 65 | E26: 69 | F26: 72
A27: Insurance | B27: 78 | C27: 75 | D27: 63 | E27: 87 | F27: 69
A28: TOTAL G&A | B28: =SUM(B20:B27) | C28: =SUM(C20:C27) | D28: =SUM(D20:D27) | E28: =SUM(E20:E27) | F28: =SUM(F20:F27)
A30: SALES & MARKETING
A31: S&M Labor | B31: 0 | C31: 147 | D31: 413 | E31: 433 | F31: 455
A32: Marketing & Supplies | B32: 30 | C32: 33 | D32: 35 | E32: 37 | F32: 38
A33: Travel | B33: 30 | C33: 32 | D33: 33 | E33: 35 | F33: 36
A34: Advertising | B34: 20 | C34: 20 | D34: 20 | E34: 21 | F34: 24
A35: TOTAL S&M | B35: =SUM(B31:B34) | C35: =SUM(C31:C34) | D35: =SUM(D31:D34) | E35: =SUM(E31:E34) | F35: =SUM(F31:F34)
A37: TOTAL OPERATING EXPENSES | B37: =B28+B35 | C37: =C28+C35 | D37: =D28+D35 | E37: =E28+E35 | F37: =F28+F35
A39: EBITDA | B39: =B16-B37 | C39: =C16-C37 | D39: =D16-D37 | E39: =E16-E37 | F39: =F16-F37
A40: EBITDA Margin % | B40: =IF(B6=0,0,B39/B6) | C40: =IF(C6=0,0,C39/C6) | D40: =IF(D6=0,0,D39/D6) | E40: =IF(E6=0,0,E39/E6) | F40: =IF(F6=0,0,F39/F6)
A42: Depreciation | B42: 500 | C42: 640 | D42: 755 | E42: 870 | F42: 870
A43: EBIT | B43: =B39-B42 | C43: =C39-C42 | D43: =D39-D42 | E43: =E39-E42 | F43: =F39-F42
A44: Zakat (2.5%) | B44: =IF(B43>0,B43*0.025,0) | C44: =IF(C43>0,C43*0.025,0) | D44: =IF(D43>0,D43*0.025,0) | E44: =IF(E43>0,E43*0.025,0) | F44: =IF(F43>0,F43*0.025,0)
A45: NET INCOME | B45: =B43-B44 | C45: =C43-C44 | D45: =D43-D44 | E45: =E43-E44 | F45: =F43-F44
A46: Net Margin % | B46: =IF(B6=0,0,B45/B6) | C46: =IF(C6=0,0,C45/C6) | D46: =IF(D6=0,0,D45/D6) | E46: =IF(E6=0,0,E45/E6) | F46: =IF(F6=0,0,F45/F6)
...

Sheet Saudi Evidence (TKG-05)
A1: SAUDI EVIDENCE PLATFORM (TKG-05)
A2: P&L Statement | SAR Thousands | Conservative
B3: 2026 | C3: 2027 | D3: 2028 | E3: 2029 | F3: 2030
A4: REVENUE
A5: 1. CHI Partnership / Govt Contract | B5: 0 | C5: 500 | D5: 2000 | E5: 4000 | F5: 7000
A6: 2. Institutional Subscriptions (B2B) | B6: 0 | C6: 300 | D6: 1500 | E6: 3500 | F6: 7000
A7: 3. Pharma Data Packages | B7: 0 | C7: 0 | D7: 500 | E7: 1500 | F7: 3000
A8: 4. CME Platform Fees | B8: 0 | C8: 200 | D8: 800 | E8: 1500 | F8: 2500
A9: TOTAL REVENUE | B9: =SUM(B5:B8) | C9: =SUM(C5:C8) | D9: =SUM(D5:D8) | E9: =SUM(E5:E8) | F9: =SUM(F5:F8)
A10: Revenue Growth % | B10: N/A | C10: =IF(B9=0,0,(C9-B9)/B9) | D10: =IF(C9=0,0,(D9-C9)/C9) | E10: =IF(D9=0,0,(E9-D9)/D9) | F10: =IF(E9=0,0,(F9-E9)/E9)
A12: DIRECT COSTS (COGS)
A13: Cloud Infrastructure (sovereign) | B13: 200 | C13: 300 | D13: 500 | E13: 800 | F13: 1200
A14: DeepEvidence API Costs | B14: 100 | C14: 200 | D14: 400 | E14: 700 | F14: 1200
A15: Content Licensing & Ingestion | B15: 50 | C15: 100 | D15: 200 | E15: 400 | F15: 600
A16: Data Processing & NLP (CII fees) | B16: 100 | C16: 150 | D16: 300 | E16: 500 | F16: 800
A17: Support & Helpdesk | B17: 50 | C17: 50 | D17: 100 | E17: 100 | F17: 200
A18: TOTAL COGS | B18: =SUM(B13:B17) | C18: =SUM(C13:C17) | D18: =SUM(D13:D17) | E18: =SUM(E13:E17) | F18: =SUM(F13:F17)
A19: GROSS PROFIT | B19: =B9-B18 | C19: =C9-C18 | D19: =D9-D18 | E19: =E9-E18 | F19: =F9-F18
A20: Gross Margin % | B20: =IF(B9=0,0,B19/B9) | C20: =IF(C9=0,0,C19/C9) | D20: =IF(D9=0,0,D19/D9) | E20: =IF(E9=0,0,E19/E9) | F20: =IF(F9=0,0,F19/F9)
A22: GENERAL & ADMINISTRATIVE
A23: Engineering Team (salaries) | B23: 1200 | C23: 1500 | D23: 1800 | E23: 2100 | F23: 2400
A24: Product & Design | B24: 300 | C24: 400 | D24: 500 | E24: 500 | F24: 600
A25: Operations & Admin | B25: 200 | C25: 250 | D25: 300 | E25: 400 | F25: 500
A26: Security & Compliance (NCA/PDPL) | B26: 150 | C26: 200 | D26: 250 | E26: 300 | F26: 300
A27: Office & Misc | B27: 150 | C27: 150 | D27: 150 | E27: 200 | F27: 200
A28: TOTAL G&A | B28: =SUM(B23:B27) | C28: =SUM(C23:C27) | D28: =SUM(D23:D27) | E28: =SUM(E23:E27) | F28: =SUM(F23:F27)
A30: SALES & MARKETING
A31: Growth Marketing | B31: 80 | C31: 150 | D31: 250 | E31: 350 | F31: 450
A32: Institutional Sales | B32: 60 | C32: 120 | D32: 200 | E32: 300 | F32: 350
A33: Partnerships & BD | B33: 40 | C33: 80 | D33: 100 | E33: 100 | F33: 150
A34: Content Marketing | B34: 20 | C34: 50 | D34: 50 | E34: 50 | F34: 50
A35: TOTAL S&M | B35: =SUM(B31:B34) | C35: =SUM(C31:C34) | D35: =SUM(D31:D34) | E35: =SUM(E31:E34) | F35: =SUM(F31:F34)
A37: TOTAL OPERATING EXPENSES | B37: =B28+B35 | C37: =C28+C35 | D37: =D28+D35 | E37: =E28+E35 | F37: =F28+F35
A39: EBITDA | B39: =B19-B37 | C39: =C19-C37 | D39: =D19-D37 | E39: =E19-E37 | F39: =F19-F37
A40: EBITDA Margin % | B40: =IF(B9=0,0,B39/B9) | C40: =IF(C9=0,0,C39/C9) | D40: =IF(D9=0,0,D39/D9) | E40: =IF(E9=0,0,E39/E9) | F40: =IF(F9=0,0,F39/F9)
A42: OPERATIONAL METRICS
A43: Headcount | B43: 6 | C43: 10 | D43: 15 | E43: 20 | F43: 25
A44: Active Clinician Users | B44: 500 | C44: 2000 | D44: 10000 | E44: 30000 | F44: 75000
A45: Knowledge Graph Nodes | B45: 16290 | C45: 50000 | D45: 250000 | E45: 1000000 | F45: 5000000
A46: Interactive MNCs | B46: 10 | C46: 70 | D46: 70 | E46: 100 | F46: 150
...

Sheet Assumptions
A1: Category | B1: Assumption | C1: Value | D1: Source / Basis
A2: GENERAL | B2: Currency | C2: SAR (thousands) | D2: All figures in SAR '000
B3: Exchange Rate | C3: 1 USD = 3.75 SAR | D3: SAMA
B4: Tax/Zakat | C4: 2.5% | D4: Zakat on Saudi entities
B5: Discount Rate | C5: 15% | D5: EM healthcare premium
B6: Terminal Growth | C6: 3% | D6: GDP-aligned
B7: Scenario | C7: Conservative | D7: 25-35% below mgmt case
A9: MARKET | B9: Healthcare Spend | C9: SAR 196B/year | D9: MOH / Vision 2030
B10: Scientific Societies | C10: 80+ | D10: SCFHS registered
B11: CME Mandate | C11: 30 credits/yr | D11: SCFHS regulation
B12: Licensed Professionals | C12: 300,000+ | D12: SCFHS registry
B13: Private Hospitals | C13: 400+ | D13: MOH
A15: WARAQA | B15: Society conversion | C15: 3>5>10>15>20 | D15: Y1-Y5
B16: APC pricing | C16: SAR 3-4K/article | D16: Intl OA competitive
B17: University adoption | C17: 1>2>5>7>10 | D17: Y1-Y5
B18: AI licensing TAM | C18: SAR 100M+ | D18: Wiley benchmark
B19: PubHelper projects | C19: 40>80>150>250>350 | D19: Y1-Y5
B20: Physician subscribers | C20: 10>50>150>300>500 | D20: Y1-Y5
A22: NAMA CRO | B22: Active trials | C22: 5>12>20>30>40 | D22: Y1-Y5
B23: Rev per trial | C23: SAR 750K-1.5M | D23: Phase-dependent
B24: Alfaisaliah pipeline | C24: Guaranteed | D24: Strategic investor
B25: Geographic scope | C25: KSA+Egypt+UAE+UK | D25: Milestone agreement
A27: NAMA ACADEMY | B27: Training pipeline | C27: 500>1.2K>2.5K>4K>5.5K | D27: Y1-Y5
B28: AaaS contracts | C28: 0>1>3>6>10 | D28: Y1-Y5
B29: SHA course fee | C29: SAR 600-1,500 | D29: SHA standard
B30: MGA bundle | C30: SAR 800-1,200/physician | D30: Cross-group product
A32: NAMA BIO | B32: Studies/year | C32: 10>15>25>30>40 | D32: Y1-Y5
B33: Price per study | C33: SAR 270-340K | D33: Market rate KSA
B34: CARE Medical ward | C34: 40 beds | D34: Partnership
B35: KSU bioanalytics | C35: Outsourced | D35: MOU signed
A37: SAUDI EVIDENCE | B37: Users | C37: 500>2K>10K>30K>75K | D37: Y1-Y5
B38: CHI partnership | C38: Target Q2-Q3 2026 | D38: Gov contract
B39: DeepEvidence API | C39: Partnership | D39: Under negotiation
B40: Knowledge graph | C40: 16K>5M nodes | D40: Y1-Y5
A42: INTER-COMPANY | B42: Waraqa>Academy | C42: SAR 400-500K/yr | D42: Internal allocation
B43: CRO>Waraqa writing | C43: SAR 300-900K/yr | D43: SLA
B44: Elimination rate | C44: ~5-8% of gross | D44: Conservative
A46: CAPITAL | B46: CRO external equity | C46: SAR 18.75M | D46: Alfaisaliah 25-35%
B47: Bio govt grant | C47: SAR 2M | D47: Non-dilutive
B48: Evidence grants | C48: SAR 10M | D48: SDAIA/RDIA target
...
