Workbook

Sheet Executive Summary
A1: WARAQA - EXECUTIVE SUMMARY
A3: 10-Year Financial Projections
A5: Revenue Metrics
A6: Y1 Revenue ($M) | B6: ='Revenue Model'!B9 -> 1.2
A7: Y5 Revenue ($M) | B7: ='Revenue Model'!F9 -> 24
A8: Y10 Revenue ($M) | B8: ='Revenue Model'!K9 -> 59.6
A9: CAGR (Y1-Y10) | B9: =('Revenue Model'!K9/'Revenue Model'!B9)^(1/9)-1 -> 0.54330466
A11: Profitability Metrics
A12: Y1 EBITDA % | B12: ='EBITDA & Cash Flow'!B12 -> -0.03
A13: Y5 EBITDA % | B13: ='EBITDA & Cash Flow'!F12 -> 0.13
A14: Y10 EBITDA % | B14: ='EBITDA & Cash Flow'!K12 -> 0.2
A15: Y1 EBITDA ($M) | B15: ='EBITDA & Cash Flow'!B11 -> -0.036
A16: Y10 EBITDA ($M) | B16: ='EBITDA & Cash Flow'!K11 -> 11.92
A18: Capital Requirements
A19: Phase 1 (Y1) | B19: ='Capital Requirements'!B5 -> 2.5
A20: Phase 2 (Y2) | B20: ='Capital Requirements'!C5 -> 0
A21: Total Capital | B21: ='Capital Requirements'!D5 -> 0

Sheet Revenue Model
A1: WARAQA - 10-YEAR REVENUE MODEL
A2: Year | B2: 2027 | C2: 2028 | D2: 2029 | E2: 2030 | F2: 2031 | G2: 2032 | H2: 2033 | I2: 2034 | J2: 2035 | K2: 2036
A3: Total Revenue Input | B3: 1.2 | C3: 3.5 | D3: 7.5 | E3: 14 | F3: 24 | G3: 31.2 | H3: 38.6 | I3: 46.3 | J3: 53.2 | K3: 59.6
A4: Journal Hosting (35%) | B4: =B3*0.35 -> 0.42 | C4: =C3*0.35 -> 1.225 | D4: =D3*0.35 -> 2.625 | E4: =E3*0.35 -> 4.9 | F4: =F3*0.35 -> 8.4 | G4: =G3*0.35 -> 10.92 | H4: =H3*0.35 -> 13.51 | I4: =I3*0.35 -> 16.205 | ... K4: =K3*0.35 -> 20.86
A5: APC (Article Processing) (20%) | B5: =B3*0.2 -> 0.24 | C5: =C3*0.2 -> 0.7 | D5: =D3*0.2 -> 1.5 | E5: =E3*0.2 -> 2.8 | F5: =F3*0.2 -> 4.8 | G5: =G3*0.2 -> 6.24 | H5: =H3*0.2 -> 7.72 | I5: =I3*0.2 -> 9.26 | ... K5: =K3*0.2 -> 11.92
A6: Evidence Synthesis (20%) | B6: =B3*0.2 -> 0.24 | C6: =C3*0.2 -> 0.7 | D6: =D3*0.2 -> 1.5 | E6: =E3*0.2 -> 2.8 | F6: =F3*0.2 -> 4.8 | G6: =G3*0.2 -> 6.24 | H6: =H3*0.2 -> 7.72 | I6: =I3*0.2 -> 9.26 | ... K6: =K3*0.2 -> 11.92
A7: Manuscript Services (10%) | B7: =B3*0.1 -> 0.12 | C7: =C3*0.1 -> 0.35 | D7: =D3*0.1 -> 0.75 | E7: =E3*0.1 -> 1.4 | F7: =F3*0.1 -> 2.4 | G7: =G3*0.1 -> 3.12 | H7: =H3*0.1 -> 3.86 | I7: =I3*0.1 -> 4.63 | ... K7: =K3*0.1 -> 5.96
A8: Data Registry (10%) | B8: =B3*0.1 -> 0.12 | C8: =C3*0.1 -> 0.35 | D8: =D3*0.1 -> 0.75 | E8: =E3*0.1 -> 1.4 | F8: =F3*0.1 -> 2.4 | G8: =G3*0.1 -> 3.12 | H8: =H3*0.1 -> 3.86 | I8: =I3*0.1 -> 4.63 | ... K8: =K3*0.1 -> 5.96
A9: TOTAL REVENUE | B9: =B3 -> 1.2 | C9: =C3 -> 3.5 | D9: =D3 -> 7.5 | E9: =E3 -> 14 | F9: =F3 -> 24 | G9: =G3 -> 31.2 | H9: =H3 -> 38.6 | I9: =I3 -> 46.3 | ... K9: =K3 -> 59.6
A11: HEADCOUNT | B11: 8 | C11: 12 | D11: 20 | E11: 30 | F11: 40 | G11: 50 | H11: 58 | I11: 65 | J11: 72 | K11: 78
A12: Revenue per Employee | B12: =B9/B11 -> 0.15 | C12: =C9/C11 -> 0.29166667 | D12: =D9/D11 -> 0.375 | E12: =E9/E11 -> 0.46666667 | F12: =F9/F11 -> 0.6 | G12: =G9/G11 -> 0.624 | H12: =H9/H11 -> 0.66551724 | I12: =I9/I11 -> 0.71230769 | ... K12: =K9/K11 -> 0.76410256

Sheet Cost Structure
A1: WARAQA - COST STRUCTURE ANALYSIS
A2: Year | B2: 2027 | C2: 2028 | D2: 2029 | E2: 2030 | F2: 2031 | G2: 2032 | H2: 2033 | I2: 2034 | J2: 2035 | K2: 2036
A3: REVENUE | B3: ='Revenue Model'!B9 -> 1.2 | C3: ='Revenue Model'!C9 -> 3.5 | D3: ='Revenue Model'!D9 -> 7.5 | E3: ='Revenue Model'!E9 -> 14 | F3: ='Revenue Model'!F9 -> 24 | G3: ='Revenue Model'!G9 -> 31.2 | H3: ='Revenue Model'!H9 -> 38.6 | I3: ='Revenue Model'!I9 -> 46.3 | ... K3: ='Revenue Model'!K9 -> 59.6
A4: COGS (33% of Revenue) | B4: =B3*0.33 -> 0.396 | C4: =C3*0.33 -> 1.155 | D4: =D3*0.33 -> 2.475 | E4: =E3*0.33 -> 4.62 | F4: =F3*0.33 -> 7.92 | G4: =G3*0.33 -> 10.296 | H4: =H3*0.33 -> 12.738 | I4: =I3*0.33 -> 15.279 | ... K4: =K3*0.33 -> 19.668
A5: GROSS PROFIT | B5: =B3-B4 -> 0.804 | C5: =C3-C4 -> 2.345 | D5: =D3-D4 -> 5.025 | E5: =E3-E4 -> 9.38 | F5: =F3-F4 -> 16.08 | G5: =G3-G4 -> 20.904 | H5: =H3-H4 -> 25.862 | I5: =I3-I4 -> 31.021 | ... K5: =K3-K4 -> 39.932
A6: Gross Margin % | B6: =B5/B3 -> 0.67 | C6: =C5/C3 -> 0.67 | D6: =D5/D3 -> 0.67 | E6: =E5/E3 -> 0.67 | F6: =F5/F3 -> 0.67 | G6: =G5/G3 -> 0.67 | H6: =H5/H3 -> 0.67 | I6: =I5/I3 -> 0.67 | ... K6: =K5/K3 -> 0.67
A8: OPERATING EXPENSES
A9: Technology Development | B9: =B3*0.25 -> 0.3 | C9: =C3*0.24 -> 0.84 | D9: =D3*0.23 -> 1.725 | E9: =E3*0.22 -> 3.08 | F9: =F3*0.21 -> 5.04 | G9: =G3*0.2 -> 6.24 | H9: =H3*0.19 -> 7.334 | I9: =I3*0.18 -> 8.334 | J9: =J3*0.18 -> 9.576 | K9: =K3*0.18 -> 10.728
A10: Content & Editorial | B10: =B3*0.2 -> 0.24 | C10: =C3*0.19 -> 0.665 | D10: =D3*0.18 -> 1.35 | E10: =E3*0.17 -> 2.38 | F10: =F3*0.16 -> 3.84 | G10: =G3*0.15 -> 4.68 | H10: =H3*0.15 -> 5.79 | I10: =I3*0.14 -> 6.482 | J10: =J3*0.14 -> 7.448 | K10: =K3*0.14 -> 8.344
A11: Sales & Marketing | B11: =B3*0.15 -> 0.18 | C11: =C3*0.14 -> 0.49 | D11: =D3*0.12 -> 0.9 | E11: =E3*0.11 -> 1.54 | F11: =F3*0.1 -> 2.4 | G11: =G3*0.1 -> 3.12 | H11: =H3*0.1 -> 3.86 | I11: =I3*0.09 -> 4.167 | J11: =J3*0.09 -> 4.788 | K11: =K3*0.09 -> 5.364
A12: General & Administrative | B12: =B3*0.1 -> 0.12 | C12: =C3*0.09 -> 0.315 | D12: =D3*0.08 -> 0.6 | E12: =E3*0.08 -> 1.12 | F12: =F3*0.07 -> 1.68 | G12: =G3*0.07 -> 2.184 | H12: =H3*0.07 -> 2.702 | I12: =I3*0.06 -> 2.778 | J12: =J3*0.06 -> 3.192 | K12: =K3*0.06 -> 3.576
A13: TOTAL OPEX | B13: =SUM(B9:B12) -> 0.84 | C13: =SUM(C9:C12) -> 2.31 | D13: =SUM(D9:D12) -> 4.575 | E13: =SUM(E9:E12) -> 8.12 | F13: =SUM(F9:F12) -> 12.96 | G13: =SUM(G9:G12) -> 16.224 | H13: =SUM(H9:H12) -> 19.686 | I13: =SUM(I9:I12) -> 21.761 | ... K13: =SUM(K9:K12) -> 28.012
A14: OpEx as % of Revenue | B14: =B13/B3 -> 0.7 | C14: =C13/C3 -> 0.66 | D14: =D13/D3 -> 0.61 | E14: =E13/E3 -> 0.58 | F14: =F13/F3 -> 0.54 | G14: =G13/G3 -> 0.52 | H14: =H13/H3 -> 0.51 | I14: =I13/I3 -> 0.47 | ... K14: =K13/K3 -> 0.47

Sheet EBITDA & Cash Flow
A1: WARAQA - EBITDA & CASH FLOW PROJECTIONS
A2: Year | B2: 2027 | C2: 2028 | D2: 2029 | E2: 2030 | F2: 2031 | G2: 2032 | H2: 2033 | I2: 2034 | J2: 2035 | K2: 2036
A3: Revenue | B3: ='Revenue Model'!B9 -> 1.2 | C3: ='Revenue Model'!C9 -> 3.5 | D3: ='Revenue Model'!D9 -> 7.5 | E3: ='Revenue Model'!E9 -> 14 | F3: ='Revenue Model'!F9 -> 24 | G3: ='Revenue Model'!G9 -> 31.2 | H3: ='Revenue Model'!H9 -> 38.6 | I3: ='Revenue Model'!I9 -> 46.3 | ... K3: ='Revenue Model'!K9 -> 59.6
A4: Less: COGS | B4: ='Cost Structure'!B4 -> 0.396 | C4: ='Cost Structure'!C4 -> 1.155 | D4: ='Cost Structure'!D4 -> 2.475 | E4: ='Cost Structure'!E4 -> 4.62 | F4: ='Cost Structure'!F4 -> 7.92 | G4: ='Cost Structure'!G4 -> 10.296 | H4: ='Cost Structure'!H4 -> 12.738 | I4: ='Cost Structure'!I4 -> 15.279 | ... K4: ='Cost Structure'!K4 -> 19.668
A5: Gross Profit | B5: =B3-B4 -> 0.804 | C5: =C3-C4 -> 2.345 | D5: =D3-D4 -> 5.025 | E5: =E3-E4 -> 9.38 | F5: =F3-F4 -> 16.08 | G5: =G3-G4 -> 20.904 | H5: =H3-H4 -> 25.862 | I5: =I3-I4 -> 31.021 | ... K5: =K3-K4 -> 39.932
A6: Less: OpEx | B6: ='Cost Structure'!B13 -> 0.84 | C6: ='Cost Structure'!C13 -> 2.31 | D6: ='Cost Structure'!D13 -> 4.575 | E6: ='Cost Structure'!E13 -> 8.12 | F6: ='Cost Structure'!F13 -> 12.96 | G6: ='Cost Structure'!G13 -> 16.224 | H6: ='Cost Structure'!H13 -> 19.686 | I6: ='Cost Structure'!I13 -> 21.761 | ... K6: ='Cost Structure'!K13 -> 28.012
A7: EBITDA | B7: =B5-B6 -> -0.036 | C7: =C5-C6 -> 0.035 | D7: =D5-D6 -> 0.45 | E7: =E5-E6 -> 1.26 | F7: =F5-F6 -> 3.12 | G7: =G5-G6 -> 4.68 | H7: =H5-H6 -> 6.176 | I7: =I5-I6 -> 9.26 | ... K7: =K5-K6 -> 11.92
A8: Less: D&A (estimated 5%) | B8: =B3*0.05 -> 0.06 | C8: =C3*0.05 -> 0.175 | D8: =D3*0.05 -> 0.375 | E8: =E3*0.05 -> 0.7 | F8: =F3*0.05 -> 1.2 | G8: =G3*0.05 -> 1.56 | H8: =H3*0.05 -> 1.93 | I8: =I3*0.05 -> 2.315 | ... K8: =K3*0.05 -> 2.98
A9: EBIT (Operating Income) | B9: =B7-B8 -> -0.096 | C9: =C7-C8 -> -0.14 | D9: =D7-D8 -> 0.075 | E9: =E7-E8 -> 0.56 | F9: =F7-F8 -> 1.92 | G9: =G7-G8 -> 3.12 | H9: =H7-H8 -> 4.246 | I9: =I7-I8 -> 6.945 | ... K9: =K7-K8 -> 8.94
A11: EBITDA ($M) | B11: =B7 -> -0.036 | C11: =C7 -> 0.035 | D11: =D7 -> 0.45 | E11: =E7 -> 1.26 | F11: =F7 -> 3.12 | G11: =G7 -> 4.68 | H11: =H7 -> 6.176 | I11: =I7 -> 9.26 | ... K11: =K7 -> 11.92
A12: EBITDA Margin % | B12: =B11/B3 -> -0.03 | C12: =C11/C3 -> 0.01 | D12: =D11/D3 -> 0.06 | E12: =E11/E3 -> 0.09 | F12: =F11/F3 -> 0.13 | G12: =G11/G3 -> 0.15 | H12: =H11/H3 -> 0.16 | I12: =I11/I3 -> 0.2 | ... K12: =K11/K3 -> 0.2
A14: CASH FLOW ANALYSIS
A15: Operating Cash Flow | B15: =B7 -> -0.036 | C15: =C7 -> 0.035 | D15: =D7 -> 0.45 | E15: =E7 -> 1.26 | F15: =F7 -> 3.12 | G15: =G7 -> 4.68 | H15: =H7 -> 6.176 | I15: =I7 -> 9.26 | ... K15: =K7 -> 11.92
A16: Less: CapEx | B16: 1 | C16: 1.5 | D16: 0.5 | E16: 0.5 | F16: 0.3 | G16: 0.3 | H16: 0.2 | I16: 0.2 | J16: 0.2 | K16: 0.2
A17: Free Cash Flow | B17: =B15-B16 -> -1.036 | C17: =C15-C16 -> -1.465 | D17: =D15-D16 -> -0.05 | E17: =E15-E16 -> 0.76 | F17: =F15-F16 -> 2.82 | G17: =G15-G16 -> 4.38 | H17: =H15-H16 -> 5.976 | I17: =I15-I16 -> 9.06 | ... K17: =K15-K16 -> 11.72

Sheet Capital Requirements
A1: WARAQA - CAPITAL REQUIREMENTS & DEPLOYMENT
A2: Capital Phase | B2: Amount ($M) | C2: Timing | D2: Use of Funds
A3: Phase 1: MVP Development | B3: 1 | C3: Year 1 | D3: Platform development & market traction
A4: Phase 2: Scaling & Expansion | B4: 1.5 | C4: Year 2 | D4: Geographic expansion & feature development
A5: TOTAL CAPITAL REQUIRED | B5: =B3+B4 -> 2.5
A7: Cumulative Investment by Year
A8: Year 1 | B8: =B3 -> 1
A9: Year 2 | B9: =B8+B4 -> 2.5
A11: PAYBACK ANALYSIS
A12: Total Capital | B12: =B5 -> 2.5
A13: Y1 FCF | B13: ='EBITDA & Cash Flow'!B17 -> -1.036
A14: Y2 FCF | B14: ='EBITDA & Cash Flow'!C17 -> -1.465
A15: Y3 FCF | B15: ='EBITDA & Cash Flow'!D17 -> -0.05
A16: Cumulative FCF (Y1-Y3) | B16: =B13+B14+B15 -> -2.551

Sheet Valuation Scenarios
A1: WARAQA - VALUATION SCENARIOS
A3: YEAR 5 VALUATION (2031)
A4: Y5 EBITDA | B4: ='EBITDA & Cash Flow'!F11 -> 3.12
A5: EBITDA Multiple
A7: Scenario | B7: Multiple | C7: Enterprise Value ($M)
A8: Conservative | B8: 8 | C8: =B4*B8 -> 24.96
A9: Base Case | B9: 9 | C9: =B4*B9 -> 28.08
A10: Optimistic | B10: 10 | C10: =B4*B10 -> 31.2
A12: YEAR 10 VALUATION (2036)
A13: Y10 EBITDA | B13: ='EBITDA & Cash Flow'!K11 -> 11.92
A16: Scenario | B16: Multiple | C16: Enterprise Value ($M)
A17: Conservative | B17: 8 | C17: =B13*B17 -> 95.36
A18: Base Case | B18: 9 | C18: =B13*B18 -> 107.28
A19: Optimistic | B19: 10 | C19: =B13*B19 -> 119.2
A22: RETURN METRICS (Based on Y5 Exit)
A23: Investment Amount | B23: ='Capital Requirements'!B5 -> 2.5
A25: Scenario | B25: Exit Value | C25: MOIC
A26: Conservative | B26: =C8 -> 24.96 | C26: =B26/B23 -> 9.984
A27: Base Case | B27: =C9 -> 28.08 | C27: =B27/B23 -> 11.232
A28: Optimistic | B28: =C10 -> 31.2 | C28: =B28/B23 -> 12.48
A31: IRR ESTIMATION (5-Year Horizon)
A32: Conservative | B32: ~100%
A33: Base Case | B33: ~130%
A34: Optimistic | B34: ~150%

Sheet Assumptions
A1: WARAQA - MODEL ASSUMPTIONS
A2: REVENUE ASSUMPTIONS
A4: Base Revenue (Y1) | B4: $1.2M
A5: Growth Trajectory | B5: See Revenue Model Sheet
A6: Revenue Streams | B6: 6 diversified streams
A7: Journal Hosting % | B7: 35%
A8: APC (Article Processing) % | B8: 20%
A9: Evidence Synthesis % | B9: 20%
A10: Manuscript Services % | B10: 10%
A11: Data Registry % | B11: 10%
A12: Platform Licensing % | B12: 5%
A14: COST ASSUMPTIONS
A16: COGS % of Revenue | B16: 33% (constant)
A17: Gross Margin | B17: 67% (constant)
A18: Technology Development Y1 | B18: 25% of OpEx
A19: Technology Development Y10 | B19: 18% of OpEx
A20: Content & Editorial Y1 | B20: 20% of OpEx
A21: Content & Editorial Y10 | B21: 15% of OpEx
A22: Sales & Marketing Y1 | B22: 15% of OpEx
A23: Sales & Marketing Y10 | B23: 10% of OpEx
A24: G&A Y1 | B24: 10% of OpEx
A25: G&A Y10 | B25: 7% of OpEx
A26: D&A Estimate | B26: 5% of Revenue
A28: CAPITAL ASSUMPTIONS
A30: Phase 1 Capital (Y1) | B30: $1.0M
A31: Phase 2 Capital (Y2) | B31: $1.5M
A32: Total Capital Requirement | B32: $2.5M
A33: Phase 1 Use | B33: MVP & platform development
A34: Phase 2 Use | B34: Geographic expansion
A36: HEADCOUNT ASSUMPTIONS
A38: Y1 Headcount | B38: 8 employees
A39: Y10 Headcount | B39: 78 employees
A40: Growth Pattern | B40: Follows revenue but with leverage
A41: Revenue per Employee Y1 | B41: $150K
A42: Revenue per Employee Y10 | B42: $600K+
A44: VALUATION ASSUMPTIONS
A46: Exit Timeline | B46: Year 5 or Year 10
A47: Y5 EBITDA Multiple Range | B47: 8x - 10x
A48: Y10 EBITDA Multiple Range | B48: 8x - 10x
A49: Base Case Multiple | B49: 9x (conservative for healthcare SaaS)
...
